Workbook

Sheet Daily Grid
A1: Date | B1: Year | C1: Month | D1: Weekday | E1: AEP | F1: MA_OEP / GEP | G1: SEP_Notes | H1: Has_Event | I1: Event_Detail
A2: 45292 | B2: =YEAR($A2) -> 2024 | C2: =MONTH($A2) -> 1 | D2: =TEXT($A2,"ddd") -> Mon | E2: =IF(OR(AND(MONTH($A2)=10,DAY($A2)>=15),MONTH($A2)=11,AND(MONTH($A2)=12,DAY($A2)<=7)),1,0) -> 0 | F2: =IF(MONTH($A2)<=3,1,0) -> 1 | H2: =COUNTIF(Events!$A$2:$A$391,$A2) -> 1 | I2: =IFERROR(INDEX(Events!$E$2:$E$391,MATCH($A2,Events!$A$2:$A$391,0)),"") -> IRA phase-in: 5% coinsurance in Part D catastrophic phase eliminated; full Low-Income Subsidy (Extra Help) expanded to 150% FPL
A3: 45293 | B3: =YEAR($A3) -> 2024 | C3: =MONTH($A3) -> 1 | D3: =TEXT($A3,"ddd") -> Tue | E3: =IF(OR(AND(MONTH($A3)=10,DAY($A3)>=15),MONTH($A3)=11,AND(MONTH($A3)=12,DAY($A3)<=7)),1,0) -> 0 | F3: =IF(MONTH($A3)<=3,1,0) -> 1 | H3: =COUNTIF(Events!$A$2:$A$391,$A3) -> 0 | I3: =IFERROR(INDEX(Events!$E$2:$E$391,MATCH($A3,Events!$A$2:$A$391,0)),"")
A4: 45294 | B4: =YEAR($A4) -> 2024 | C4: =MONTH($A4) -> 1 | D4: =TEXT($A4,"ddd") -> Wed | E4: =IF(OR(AND(MONTH($A4)=10,DAY($A4)>=15),MONTH($A4)=11,AND(MONTH($A4)=12,DAY($A4)<=7)),1,0) -> 0 | F4: =IF(MONTH($A4)<=3,1,0) -> 1 | H4: =COUNTIF(Events!$A$2:$A$391,$A4) -> 0 | I4: =IFERROR(INDEX(Events!$E$2:$E$391,MATCH($A4,Events!$A$2:$A$391,0)),"")
A5: 45295 | B5: =YEAR($A5) -> 2024 | C5: =MONTH($A5) -> 1 | D5: =TEXT($A5,"ddd") -> Thu | E5: =IF(OR(AND(MONTH($A5)=10,DAY($A5)>=15),MONTH($A5)=11,AND(MONTH($A5)=12,DAY($A5)<=7)),1,0) -> 0 | F5: =IF(MONTH($A5)<=3,1,0) -> 1 | H5: =COUNTIF(Events!$A$2:$A$391,$A5) -> 0 | I5: =IFERROR(INDEX(Events!$E$2:$E$391,MATCH($A5,Events!$A$2:$A$391,0)),"")
A6: 45296 | B6: =YEAR($A6) -> 2024 | C6: =MONTH($A6) -> 1 | D6: =TEXT($A6,"ddd") -> Fri | E6: =IF(OR(AND(MONTH($A6)=10,DAY($A6)>=15),MONTH($A6)=11,AND(MONTH($A6)=12,DAY($A6)<=7)),1,0) -> 0 | F6: =IF(MONTH($A6)<=3,1,0) -> 1 | G6: Severe Storm begin: [WA] | H6: =COUNTIF(Events!$A$2:$A$391,$A6) -> 0 | I6: =IFERROR(INDEX(Events!$E$2:$E$391,MATCH($A6,Events!$A$2:$A$391,0)),"")
A7: 45297 | B7: =YEAR($A7) -> 2024 | C7: =MONTH($A7) -> 1 | D7: =TEXT($A7,"ddd") -> Sat | E7: =IF(OR(AND(MONTH($A7)=10,DAY($A7)>=15),MONTH($A7)=11,AND(MONTH($A7)=12,DAY($A7)<=7)),1,0) -> 0 | F7: =IF(MONTH($A7)<=3,1,0) -> 1 | H7: =COUNTIF(Events!$A$2:$A$391,$A7) -> 0 | I7: =IFERROR(INDEX(Events!$E$2:$E$391,MATCH($A7,Events!$A$2:$A$391,0)),"")
A8: 45298 | B8: =YEAR($A8) -> 2024 | C8: =MONTH($A8) -> 1 | D8: =TEXT($A8,"ddd") -> Sun | E8: =IF(OR(AND(MONTH($A8)=10,DAY($A8)>=15),MONTH($A8)=11,AND(MONTH($A8)=12,DAY($A8)<=7)),1,0) -> 0 | F8: =IF(MONTH($A8)<=3,1,0) -> 1 | H8: =COUNTIF(Events!$A$2:$A$391,$A8) -> 0 | I8: =IFERROR(INDEX(Events!$E$2:$E$391,MATCH($A8,Events!$A$2:$A$391,0)),"")
A9: 45299 | B9: =YEAR($A9) -> 2024 | C9: =MONTH($A9) -> 1 | D9: =TEXT($A9,"ddd") -> Mon | E9: =IF(OR(AND(MONTH($A9)=10,DAY($A9)>=15),MONTH($A9)=11,AND(MONTH($A9)=12,DAY($A9)<=7)),1,0) -> 0 | F9: =IF(MONTH($A9)<=3,1,0) -> 1 | H9: =COUNTIF(Events!$A$2:$A$391,$A9) -> 0 | I9: =IFERROR(INDEX(Events!$E$2:$E$391,MATCH($A9,Events!$A$2:$A$391,0)),"")
A10: 45300 | B10: =YEAR($A10) -> 2024 | C10: =MONTH($A10) -> 1 | D10: =TEXT($A10,"ddd") -> Tue | E10: =IF(OR(AND(MONTH($A10)=10,DAY($A10)>=15),MONTH($A10)=11,AND(MONTH($A10)=12,DAY($A10)<=7)),1,0) -> 0 | F10: =IF(MONTH($A10)<=3,1,0) -> 1 | H10: =COUNTIF(Events!$A$2:$A$391,$A10) -> 0 | I10: =IFERROR(INDEX(Events!$E$2:$E$391,MATCH($A10,Events!$A$2:$A$391,0)),"")
A11: 45301 | B11: =YEAR($A11) -> 2024 | C11: =MONTH($A11) -> 1 | D11: =TEXT($A11,"ddd") -> Wed | E11: =IF(OR(AND(MONTH($A11)=10,DAY($A11)>=15),MONTH($A11)=11,AND(MONTH($A11)=12,DAY($A11)<=7)),1,0) -> 0 | F11: =IF(MONTH($A11)<=3,1,0) -> 1 | H11: =COUNTIF(Events!$A$2:$A$391,$A11) -> 0 | I11: =IFERROR(INDEX(Events!$E$2:$E$391,MATCH($A11,Events!$A$2:$A$391,0)),"")
A12: 45302 | B12: =YEAR($A12) -> 2024 | C12: =MONTH($A12) -> 1 | D12: =TEXT($A12,"ddd") -> Thu | E12: =IF(OR(AND(MONTH($A12)=10,DAY($A12)>=15),MONTH($A12)=11,AND(MONTH($A12)=12,DAY($A12)<=7)),1,0) -> 0 | F12: =IF(MONTH($A12)<=3,1,0) -> 1 | H12: =COUNTIF(Events!$A$2:$A$391,$A12) -> 0 | I12: =IFERROR(INDEX(Events!$E$2:$E$391,MATCH($A12,Events!$A$2:$A$391,0)),"")
A13: 45303 | B13: =YEAR($A13) -> 2024 | C13: =MONTH($A13) -> 1 | D13: =TEXT($A13,"ddd") -> Fri | E13: =IF(OR(AND(MONTH($A13)=10,DAY($A13)>=15),MONTH($A13)=11,AND(MONTH($A13)=12,DAY($A13)<=7)),1,0) -> 0 | F13: =IF(MONTH($A13)<=3,1,0) -> 1 | H13: =COUNTIF(Events!$A$2:$A$391,$A13) -> 0 | I13: =IFERROR(INDEX(Events!$E$2:$E$391,MATCH($A13,Events!$A$2:$A$391,0)),"")
A14: 45304 | B14: =YEAR($A14) -> 2024 | C14: =MONTH($A14) -> 1 | D14: =TEXT($A14,"ddd") -> Sat | E14: =IF(OR(AND(MONTH($A14)=10,DAY($A14)>=15),MONTH($A14)=11,AND(MONTH($A14)=12,DAY($A14)<=7)),1,0) -> 0 | F14: =IF(MONTH($A14)<=3,1,0) -> 1 | H14: =COUNTIF(Events!$A$2:$A$391,$A14) -> 0 | I14: =IFERROR(INDEX(Events!$E$2:$E$391,MATCH($A14,Events!$A$2:$A$391,0)),"")
A15: 45305 | B15: =YEAR($A15) -> 2024 | C15: =MONTH($A15) -> 1 | D15: =TEXT($A15,"ddd") -> Sun | E15: =IF(OR(AND(MONTH($A15)=10,DAY($A15)>=15),MONTH($A15)=11,AND(MONTH($A15)=12,DAY($A15)<=7)),1,0) -> 0 | F15: =IF(MONTH($A15)<=3,1,0) -> 1 | H15: =COUNTIF(Events!$A$2:$A$391,$A15) -> 0 | I15: =IFERROR(INDEX(Events!$E$2:$E$391,MATCH($A15,Events!$A$2:$A$391,0)),"")
A16: 45306 | B16: =YEAR($A16) -> 2024 | C16: =MONTH($A16) -> 1 | D16: =TEXT($A16,"ddd") -> Mon | E16: =IF(OR(AND(MONTH($A16)=10,DAY($A16)>=15),MONTH($A16)=11,AND(MONTH($A16)=12,DAY($A16)<=7)),1,0) -> 0 | F16: =IF(MONTH($A16)<=3,1,0) -> 1 | H16: =COUNTIF(Events!$A$2:$A$391,$A16) -> 0 | I16: =IFERROR(INDEX(Events!$E$2:$E$391,MATCH($A16,Events!$A$2:$A$391,0)),"")
A17: 45307 | B17: =YEAR($A17) -> 2024 | C17: =MONTH($A17) -> 1 | D17: =TEXT($A17,"ddd") -> Tue | E17: =IF(OR(AND(MONTH($A17)=10,DAY($A17)>=15),MONTH($A17)=11,AND(MONTH($A17)=12,DAY($A17)<=7)),1,0) -> 0 | F17: =IF(MONTH($A17)<=3,1,0) -> 1 | H17: =COUNTIF(Events!$A$2:$A$391,$A17) -> 0 | I17: =IFERROR(INDEX(Events!$E$2:$E$391,MATCH($A17,Events!$A$2:$A$391,0)),"")
A18: 45308 | B18: =YEAR($A18) -> 2024 | C18: =MONTH($A18) -> 1 | D18: =TEXT($A18,"ddd") -> Wed | E18: =IF(OR(AND(MONTH($A18)=10,DAY($A18)>=15),MONTH($A18)=11,AND(MONTH($A18)=12,DAY($A18)<=7)),1,0) -> 0 | F18: =IF(MONTH($A18)<=3,1,0) -> 1 | H18: =COUNTIF(Events!$A$2:$A$391,$A18) -> 0 | I18: =IFERROR(INDEX(Events!$E$2:$E$391,MATCH($A18,Events!$A$2:$A$391,0)),"")
... A29: 45319 | B29: =YEAR($A29) -> 2024 | C29: =MONTH($A29) -> 1 | D29: =TEXT($A29,"ddd") -> Sun | E29: =IF(OR(AND(MONTH($A29)=10,DAY($A29)>=15),MONTH($A29)=11,AND(MONTH($A29)=12,DAY($A29)<=7)),1,0) -> 0 | F29: =IF(MONTH($A29)<=3,1,0) -> 1 | H29: =COUNTIF(Events!$A$2:$A$391,$A29) -> 0 | I29: =IFERROR(INDEX(Events!$E$2:$E$391,MATCH($A29,Events!$A$2:$A$391,0)),"")
A30: 45320 | B30: =YEAR($A30) -> 2024 | C30: =MONTH($A30) -> 1 | D30: =TEXT($A30,"ddd") -> Mon | E30: =IF(OR(AND(MONTH($A30)=10,DAY($A30)>=15),MONTH($A30)=11,AND(MONTH($A30)=12,DAY($A30)<=7)),1,0) -> 0 | F30: =IF(MONTH($A30)<=3,1,0) -> 1 | G30: Severe Storm End: [WA] | H30: =COUNTIF(Events!$A$2:$A$391,$A30) -> 0 | I30: =IFERROR(INDEX(Events!$E$2:$E$391,MATCH($A30,Events!$A$2:$A$391,0)),"")
A31: 45321 | B31: =YEAR($A31) -> 2024 | C31: =MONTH($A31) -> 1 | D31: =TEXT($A31,"ddd") -> Tue | E31: =IF(OR(AND(MONTH($A31)=10,DAY($A31)>=15),MONTH($A31)=11,AND(MONTH($A31)=12,DAY($A31)<=7)),1,0) -> 0 | F31: =IF(MONTH($A31)<=3,1,0) -> 1 | G31: SEP open: [WA] | H31: =COUNTIF(Events!$A$2:$A$391,$A31) -> 0 | I31: =IFERROR(INDEX(Events!$E$2:$E$391,MATCH($A31,Events!$A$2:$A$391,0)),"")
A32: 45322 | B32: =YEAR($A32) -> 2024 | C32: =MONTH($A32) -> 1 | D32: =TEXT($A32,"ddd") -> Wed | E32: =IF(OR(AND(MONTH($A32)=10,DAY($A32)>=15),MONTH($A32)=11,AND(MONTH($A32)=12,DAY($A32)<=7)),1,0) -> 0 | F32: =IF(MONTH($A32)<=3,1,0) -> 1 | H32: =COUNTIF(Events!$A$2:$A$391,$A32) -> 1 | I32: =IFERROR(INDEX(Events!$E$2:$E$391,MATCH($A32,Events!$A$2:$A$391,0)),"") -> CY2025 Advance Notice released: proposed +3.70% avg payment; year 2 of 3-year phase-in of 2024 CMS-HCC (V28) risk model at 67/33 blend; comments due 3/1/2024
A33: 45323 | B33: =YEAR($A33) -> 2024 | C33: =MONTH($A33) -> 2 | D33: =TEXT($A33,"ddd") -> Thu | E33: =IF(OR(AND(MONTH($A33)=10,DAY($A33)>=15),MONTH($A33)=11,AND(MONTH($A33)=12,DAY($A33)<=7)),1,0) -> 0 | F33: =IF(MONTH($A33)<=3,1,0) -> 1 | H33: =COUNTIF(Events!$A$2:$A$391,$A33) -> 0 | I33: =IFERROR(INDEX(Events!$E$2:$E$391,MATCH($A33,Events!$A$2:$A$391,0)),"")
A34: 45324 | B34: =YEAR($A34) -> 2024 | C34: =MONTH($A34) -> 2 | D34: =TEXT($A34,"ddd") -> Fri | E34: =IF(OR(AND(MONTH($A34)=10,DAY($A34)>=15),MONTH($A34)=11,AND(MONTH($A34)=12,DAY($A34)<=7)),1,0) -> 0 | F34: =IF(MONTH($A34)<=3,1,0) -> 1 | H34: =COUNTIF(Events!$A$2:$A$391,$A34) -> 0 | I34: =IFERROR(INDEX(Events!$E$2:$E$391,MATCH($A34,Events!$A$2:$A$391,0)),"")
A35: 45325 | B35: =YEAR($A35) -> 2024 | C35: =MONTH($A35) -> 2 | D35: =TEXT($A35,"ddd") -> Sat | E35: =IF(OR(AND(MONTH($A35)=10,DAY($A35)>=15),MONTH($A35)=11,AND(MONTH($A35)=12,DAY($A35)<=7)),1,0) -> 0 | F35: =IF(MONTH($A35)<=3,1,0) -> 1 | H35: =COUNTIF(Events!$A$2:$A$391,$A35) -> 0 | I35: =IFERROR(INDEX(Events!$E$2:$E$391,MATCH($A35,Events!$A$2:$A$391,0)),"")
A36: 45326 | B36: =YEAR($A36) -> 2024 | C36: =MONTH($A36) -> 2 | D36: =TEXT($A36,"ddd") -> Sun | E36: =IF(OR(AND(MONTH($A36)=10,DAY($A36)>=15),MONTH($A36)=11,AND(MONTH($A36)=12,DAY($A36)<=7)),1,0) -> 0 | F36: =IF(MONTH($A36)<=3,1,0) -> 1 | H36: =COUNTIF(Events!$A$2:$A$391,$A36) -> 0 | I36: =IFERROR(INDEX(Events!$E$2:$E$391,MATCH($A36,Events!$A$2:$A$391,0)),"")
A37: 45327 | B37: =YEAR($A37) -> 2024 | C37: =MONTH($A37) -> 2 | D37: =TEXT($A37,"ddd") -> Mon | E37: =IF(OR(AND(MONTH($A37)=10,DAY($A37)>=15),MONTH($A37)=11,AND(MONTH($A37)=12,DAY($A37)<=7)),1,0) -> 0 | F37: =IF(MONTH($A37)<=3,1,0) -> 1 | H37: =COUNTIF(Events!$A$2:$A$391,$A37) -> 0 | I37: =IFERROR(INDEX(Events!$E$2:$E$391,MATCH($A37,Events!$A$2:$A$391,0)),"")
A38: 45328 | B38: =YEAR($A38) -> 2024 | C38: =MONTH($A38) -> 2 | D38: =TEXT($A38,"ddd") -> Tue | E38: =IF(OR(AND(MONTH($A38)=10,DAY($A38)>=15),MONTH($A38)=11,AND(MONTH($A38)=12,DAY($A38)<=7)),1,0) -> 0 | F38: =IF(MONTH($A38)<=3,1,0) -> 1 | H38: =COUNTIF(Events!$A$2:$A$391,$A38) -> 0 | I38: =IFERROR(INDEX(Events!$E$2:$E$391,MATCH($A38,Events!$A$2:$A$391,0)),"")
A39: 45329 | B39: =YEAR($A39) -> 2024 | C39: =MONTH($A39) -> 2 | D39: =TEXT($A39,"ddd") -> Wed | E39: =IF(OR(AND(MONTH($A39)=10,DAY($A39)>=15),MONTH($A39)=11,AND(MONTH($A39)=12,DAY($A39)<=7)),1,0) -> 0 | F39: =IF(MONTH($A39)<=3,1,0) -> 1 | H39: =COUNTIF(Events!$A$2:$A$391,$A39) -> 0 | I39: =IFERROR(INDEX(Events!$E$2:$E$391,MATCH($A39,Events!$A$2:$A$391,0)),"")
A40: 45330 | B40: =YEAR($A40) -> 2024 | C40: =MONTH($A40) -> 2 | D40: =TEXT($A40,"ddd") -> Thu | E40: =IF(OR(AND(MONTH($A40)=10,DAY($A40)>=15),MONTH($A40)=11,AND(MONTH($A40)=12,DAY($A40)<=7)),1,0) -> 0 | F40: =IF(MONTH($A40)<=3,1,0) -> 1 | H40: =COUNTIF(Events!$A$2:$A$391,$A40) -> 0 | I40: =IFERROR(INDEX(Events!$E$2:$E$391,MATCH($A40,Events!$A$2:$A$391,0)),"")
A41: 45331 | B41: =YEAR($A41) -> 2024 | C41: =MONTH($A41) -> 2 | D41: =TEXT($A41,"ddd") -> Fri | E41: =IF(OR(AND(MONTH($A41)=10,DAY($A41)>=15),MONTH($A41)=11,AND(MONTH($A41)=12,DAY($A41)<=7)),1,0) -> 0 | F41: =IF(MONTH($A41)<=3,1,0) -> 1 | H41: =COUNTIF(Events!$A$2:$A$391,$A41) -> 0 | I41: =IFERROR(INDEX(Events!$E$2:$E$391,MATCH($A41,Events!$A$2:$A$391,0)),"")
A42: 45332 | B42: =YEAR($A42) -> 2024 | C42: =MONTH($A42) -> 2 | D42: =TEXT($A42,"ddd") -> Sat | E42: =IF(OR(AND(MONTH($A42)=10,DAY($A42)>=15),MONTH($A42)=11,AND(MONTH($A42)=12,DAY($A42)<=7)),1,0) -> 0 | F42: =IF(MONTH($A42)<=3,1,0) -> 1 | H42: =COUNTIF(Events!$A$2:$A$391,$A42) -> 0 | I42: =IFERROR(INDEX(Events!$E$2:$E$391,MATCH($A42,Events!$A$2:$A$391,0)),"")
A43: 45333 | B43: =YEAR($A43) -> 2024 | C43: =MONTH($A43) -> 2 | D43: =TEXT($A43,"ddd") -> Sun | E43: =IF(OR(AND(MONTH($A43)=10,DAY($A43)>=15),MONTH($A43)=11,AND(MONTH($A43)=12,DAY($A43)<=7)),1,0) -> 0 | F43: =IF(MONTH($A43)<=3,1,0) -> 1 | H43: =COUNTIF(Events!$A$2:$A$391,$A43) -> 0 | I43: =IFERROR(INDEX(Events!$E$2:$E$391,MATCH($A43,Events!$A$2:$A$391,0)),"")
... A883: 46173 | B883: =YEAR($A883) -> 2026 | C883: =MONTH($A883) -> 5 | D883: =TEXT($A883,"ddd") -> Sun | E883: =IF(OR(AND(MONTH($A883)=10,DAY($A883)>=15),MONTH($A883)=11,AND(MONTH($A883)=12,DAY($A883)<=7)),1,0) -> 0 | F883: =IF(MONTH($A883)<=3,1,0) -> 0 | H883: =COUNTIF(Events!$A$2:$A$391,$A883) -> 0 | I883: =IFERROR(INDEX(Events!$E$2:$E$391,MATCH($A883,Events!$A$2:$A$391,0)),"")

Sheet Events
A1: Date | B1: Event_Type | C1: Affects | D1: Date_Type | E1: Description | F1: Source
A2: 45292 | B2: Legislation | C2: Part D | D2: Effective | E2: IRA phase-in: 5% coinsurance in Part D catastrophic phase eliminated; full Low-Income Subsidy (Extra Help) expanded to 150% FPL | F2: https://www.cms.gov/newsroom/fact-sheets/2024-medicare-advantage-and-part-d-final-rule-cms-4201-f
A3: 45322 | B3: Rate Announcement | C3: MA / Part D | D3: Announced | E3: CY2025 Advance Notice released: proposed +3.70% avg payment; year 2 of 3-year phase-in of 2024 CMS-HCC (V28) risk model at 67/33 blend; comments due 3/1/2024 | F3: https://www.cms.gov/newsroom/fact-sheets/2025-medicare-advantage-part-d-advance-notice-fact-sheet
A4: 45383 | B4: Rate Announcement | C4: MA / Part D | D4: Announced | E4: CY2025 Rate Announcement: final MA capitation rates (+3.70% avg) and Part C/D payment policies | F4: https://www.cms.gov/newsroom/fact-sheets/2026-medicare-advantage-part-d-rate-announcement
A5: 45386 | B5: CMS Rule | C5: MA / Part D / D-SNP | D5: Announced | E5: CY2025 MA & Part D Final Rule (CMS-4205-F): fixed agent/broker compensation (+$100 initial), TPMO one-to-one consent for data sharing, mid-year unused-benefits notice, SSBCI evidence requirements, dual/LIS SEP overhaul, D-SNP look-alike threshold phase-down, behavioral health network adequacy | F5: https://www.cms.gov/newsroom/fact-sheets/contract-year-2025-medicare-advantage-part-d-final-rule-cms-4205-f
A6: 45446 | B6: CMS Rule | C6: MA / Part D | D6: Effective | E6: CY2025 Final Rule regulations take effect (most provisions apply to coverage beginning 1/1/2025; agent/broker compensation changes apply beginning with Fall 2024 AEP) | F6: https://www.federalregister.gov/documents/2024/04/23/2024-07105/medicare-program-changes-to-the-medicare-advantage-and-the-medicare-prescription-drug-benefit
A7: 45566 | B7: Enrollment Milestone | C7: MA / Part D | D7: Effective | E7: CY2025 plan marketing begins; plan landscape/benefit info for 2025 released ahead of AEP; new agent/broker fixed compensation applies to Fall 2024 AEP enrollments | F7: https://www.cms.gov/newsroom/fact-sheets/contract-year-2025-medicare-advantage-part-d-final-rule-cms-4205-f
A8: 45575 | B8: Plan Landscape Release | C8: MA / Part D | D8: Announced | E8: 2025 Star Ratings published on Medicare Plan Finder: sharp industry decline - only 7 MA-PD contracts earned 5 stars (vs 38 for 2024); avg rating fell to ~3.92; drives 2026 quality bonus payments | F8: https://www.cms.gov/newsroom/fact-sheets/2025-medicare-advantage-part-d-star-ratings
A9: 45622 | B9: CMS Rule | C9: MA / Part D / D-SNP | D9: Announced | E9: CY2026 Proposed Rule (CMS-4208-P): proposed anti-obesity med coverage in Part D, AI guardrails, prior-auth/UM limits (published in Federal Register 12/10/2024; comments due 1/27/2025; several proposals later NOT finalized) | F9: https://www.cms.gov/newsroom/fact-sheets/contract-year-2026-policy-and-technical-changes-medicare-advantage-program-medicare-prescription
A10: 45658 | B10: Legislation | C10: Part D / MA / D-SNP | D10: Effective | E10: IRA: $2,000 annual Part D OOP cap begins; coverage gap eliminated (3-phase benefit); Medicare Prescription Payment Plan launches; Manufacturer Discount Program replaces Coverage Gap Discount Program; CY2025 Final Rule provisions apply incl. monthly integrated-care SEP for duals (replaces quarterly dual SEP) and D-SNP look-alike threshold lowered to 70% | F10: https://www.cms.gov/newsroom/fact-sheets/2025-medicare-advantage-part-d-advance-notice-fact-sheet ; https://www.cms.gov/newsroom/fact-sheets/contract-year-2025-medicare-advantage-part-d-final-rule-cms-4205-f
A11: 45667 | B11: Rate Announcement | C11: MA / Part D | D11: Announced | E11: CY2026 Advance Notice released: proposed +4.33% avg payment (~$21B); final year of V28 risk model phase-in; comments due 2/10/2025 | F11: https://www.cms.gov/newsroom/fact-sheets/2026-medicare-advantage-part-d-advance-notice-fact-sheet
A12: 45751 | B12: CMS Rule | C12: MA / Part D / D-SNP | D12: Announced | E12: CY2026 Final Rule (CMS-4208-F): scaled back vs proposed (dropped anti-obesity meds, AI guardrails, health equity analysis); finalized inpatient prior-auth protections, appeals loophole fixes, SSBCI non-allowable list, Rx Payment Plan auto-renewal, D-SNP integrated ID cards/HRAs by 2027 | F12: https://www.cms.gov/newsroom/fact-sheets/contract-year-2026-policy-and-technical-changes-medicare-advantage-program-medicare-prescription-final
A13: 45754 | B13: Rate Announcement | C13: MA / Part D | D13: Announced | E13: CY2026 Rate Announcement: +5.06% avg payment (~$25B, up from proposed 4.33%); V28 risk model phase-in complete (100%); Final CY2026 Part D Redesign Instructions | F13: https://www.cms.gov/newsroom/fact-sheets/2026-medicare-advantage-part-d-rate-announcement
... A22: 46118 | B22: Rate Announcement | C22: MA / Part D | D22: Announced | E22: CY2027 Rate Announcement: finalized +2.48% avg payment (~$13B, sharply up from proposed 0.09% after industry lobbying); kept 2024 (V28) risk model instead of proposed update; finalized exclusion of unlinked chart-review diagnoses from risk scores | F22: https://www.cms.gov/files/document/2027-announcement.pdf ; https://www.aha.org/news/headline/2026-04-06-cms-finalizes-medicare-advantage-rates-cy-2027

Sheet FEMA Disasters
A1: Disaster_Num | B1: State | C1: Decl_Type | D1: Incident_Type | E1: Title | F1: Incident_Begin | G1: Incident_End | H1: Declaration_Date | I1: IA_Declared | J1: Designated_Areas | K1: SEP_End_Est
A2: 4775 | B2: WA | C2: DR | D2: Severe Storm | E2: SEVERE WINTER STORMS, STRAIGHT-LINE WINDS, FLOODING, LANDSLIDES, AND MUDSLIDES | F2: 45296 | G2: 45320 | H2: 45410 | I2: FALSE | J2: 17 | K2: 45382
A3: 4774 | B3: KS | C3: DR | D3: Winter Storm | E3: SEVERE WINTER STORM | F3: 45299 | G3: 45307 | H3: 45410 | I3: FALSE | J3: 17 | K3: 45382
A4: 4764 | B4: ME | C4: DR | D4: Severe Storm | E4: SEVERE STORMS AND FLOODING | F4: 45300 | G4: 45304 | H4: 45371 | I4: FALSE | J4: 8 | K4: 45382
A5: 4766 | B5: RI | C5: DR | D5: Severe Storm | E5: SEVERE STORMS AND FLOODING | F5: 45300 | G5: 45304 | H5: 45371 | I5: FALSE | J5: 4 | K5: 45382
A6: 4770 | B6: VT | C6: DR | D6: Severe Storm | E6: SEVERE WINTER STORM | F6: 45300 | G6: 45304 | H6: 45401 | I6: FALSE | J6: 5 | K6: 45382
A7: 4771 | B7: NH | C7: DR | D7: Severe Storm | E7: SEVERE STORMS AND FLOODING | F7: 45300 | G7: 45305 | H7: 45401 | I7: FALSE | J7: 2 | K7: 45382
A8: 3604 | B8: CT | C8: EM | D8: Severe Storm | E8: SEVERE STORMS, FLOODING, AND A POTENTIAL DAM BREACH | F8: 45301 | G8: 45304 | H8: 45304 | I8: FALSE | J8: 3 | K8: 45382
A9: 4768 | B9: OR | C9: DR | D9: Severe Storm | E9: SEVERE WINTER STORMS, STRAIGHT-LINE WINDS, LANDSLIDES, AND MUDSLIDES | F9: 45301 | G9: 45313 | H9: 45395 | I9: FALSE | J9: 13 | K9: 45382
A10: 4758 | B10: CA | C10: DR | D10: Flood | E10: SEVERE STORM AND FLOODING | F10: 45312 | G10: 45314 | H10: 45341 | I10: FALSE | J10: 1 | K10: 45382
A11: 4773 | B11: CA | C11: DR | D11: Severe Storm | E11: SEVERE WINTER STORM | F11: 45321 | G11: 45322 | H11: 45401 | I11: FALSE | J11: 1 | K11: 45382
A12: 4769 | B12: CA | C12: DR | D12: Severe Storm | E12: SEVERE WINTER STORMS, TORNADOES, FLOODING, LANDSLIDES, AND MUDSLIDES | F12: 45322 | G12: 45331 | H12: 45395 | I12: FALSE | J12: 9 | K12: 45412
A13: 4772 | B13: CA | C13: DR | D13: Severe Storm | E13: SEVERE STORMS AND FLOODING | F13: 45322 | G13: 45331 | H13: 45401 | I13: FALSE | J13: 1 | K13: 45412
... A38: 4794 | B38: FL | C38: DR | D38: Severe Storm | E38: SEVERE STORMS, STRAIGHT-LINE WINDS, AND TORNADOES | F38: 45422 | G38: 45422 | H38: 45460 | I38: FALSE | J38: 13 | K38: 45504
A39: 5492 | B39: NM | C39: FM | D39: Fire | E39: BLUE 2 FIRE | F39: 45428 | H39: 45438 | I39: FALSE | J39: 1
A40: 4791 | B40: OK | C40: DR | D40: Severe Storm | E40: SEVERE STORMS, STRAIGHT-LINE WINDS, TORNADOES, AND FLOODING | F40: 45431 | G40: 45440 | H40: 45457 | I40: FALSE | J40: 10 | K40: 45504
A41: 4803 | B41: MO | C41: DR | D41: Severe Storm | E41: SEVERE STORMS, STRAIGHT-LINE WINDS, TORNADOES, AND FLOODING | F41: 45431 | G41: 45439 | H41: 45496 | I41: FALSE | J41: 15 | K41: 45504
A42: 4811 | B42: KS | C42: DR | D42: Severe Storm | E42: SEVERE STORM, STRAIGHT-LINE WINDS, TORNADOES, AND FLOODING | F42: 45431 | G42: 45431 | H42: 45524 | I42: FALSE | J42: 14 | K42: 45504
A43: 4784 | B43: IA | C43: DR | D43: Severe Storm | E43: SEVERE STORMS, TORNADOES, AND FLOODING | F43: 45432 | G43: 45443 | H43: 45436 | I43: FALSE | J43: 29 | K43: 45504
A44: 4808 | B44: NE | C44: DR | D44: Severe Storm | E44: SEVERE STORMS, STRAIGHT-LINE WINDS, TORNADOES, AND FLOODING | F44: 45432 | G44: 45446 | H44: 45524 | I44: FALSE | J44: 19 | K44: 45535
A45: 4804 | B45: KY | C45: DR | D45: Severe Storm | E45: SEVERE STORMS, STRAIGHT-LINE WINDS, TORNADOES, LANDSLIDES, AND MUDSLIDES | F45: 45433 | G45: 45439 | H45: 45496 | I45: FALSE | J45: 58 | K45: 45504
A46: 4788 | B46: AR | C46: DR | D46: Severe Storm | E46: SEVERE STORMS, STRAIGHT-LINE WINDS, TORNADOES, AND FLOODING | F46: 45436 | G46: 45439 | H46: 45442 | I46: FALSE | J46: 11 | K46: 45504
A47: 5493 | B47: AZ | C47: FM | D47: Fire | E47: SIMMONS FIRE | F47: 45440 | G47: 45443 | H47: 45441 | I47: FALSE | J47: 1 | K47: 45504
A48: 5494 | B48: NV | C48: FM | D48: Fire | E48: TRAIL FIRE | F48: 45454 | G48: 45456 | H48: 45454 | I48: FALSE | J48: 1 | K48: 45535
A49: 5495 | B49: NV | C49: FM | D49: Fire | E49: SULLIVAN FIRE | F49: 45454 | G49: 45455 | H49: 45455 | I49: FALSE | J49: 1 | K49: 45535
A50: 5496 | B50: AZ | C50: FM | D50: Fire | E50: ROSE FIRE | F50: 45455 | G50: 45457 | H50: 45455 | I50: FALSE | J50: 1 | K50: 45535
A51: 4796 | B51: IA | C51: DR | D51: Severe Storm | E51: SEVERE STORMS, FLOODING, STRAIGHT-LINE WINDS, AND TORNADOES | F51: 45459 | G51: 45496 | H51: 45467 | I51: FALSE | J51: 29 | K51: 45565
... A54: 4795 | B54: NM | C54: DR | D54: Fire | E54: SOUTH FORK FIRE, SALT FIRE, AND FLOODING | F54: 45460 | G54: 45524 | H54: 45463 | I54: FALSE | J54: 5 | K54: 45596
A55: 5497 | B55: NM | C55: FM | D55: Fire | E55: SOUTH FORK FIRE | F55: 45460 | H55: 45460 | I55: FALSE | J55: 3
A56: 5498 | B56: NM | C56: FM | D56: Fire | E56: SALT FIRE | F56: 45460 | H56: 45461 | I56: FALSE | J56: 3
A57: 4822 | B57: NE | C57: DR | D57: Severe Storm | E57: SEVERE STORMS, STRAIGHT-LINE WINDS, TORNADOES, AND FLOODING | F57: 45462 | G57: 45481 | H57: 45559 | I57: FALSE | J57: 17 | K57: 45565
A58: 4809 | B58: NM | C58: DR | D58: Flood | E58: SEVERE STORMS AND FLOODING | F58: 45463 | G58: 45464 | H58: 45524 | I58: FALSE | J58: 1 | K58: 45535
A59: 4823 | B59: WA | C59: DR | D59: Fire | E59: WILDFIRES | F59: 45465 | G59: 45481 | H59: 45559 | I59: FALSE | J59: 1 | K59: 45565
A60: 5499 | B60: WA | C60: FM | D60: Fire | E60: SLIDE RANCH FIRE | F60: 45465 | G60: 45484 | H60: 45466 | I60: FALSE | J60: 2 | K60: 45565
A61: 5500 | B61: OR | C61: FM | D61: Fire | E61: DARLENE 3 FIRE | F61: 45468 | H61: 45468 | I61: FALSE | J61: 1
A62: 4824 | B62: KS | C62: DR | D62: Severe Storm | E62: SEVERE STORMS, STRAIGHT-LINE WINDS, TORNADOES, AND FLOODING | F62: 45469 | G62: 45480 | H62: 45559 | I62: FALSE | J62: 17 | K62: 45565
A63: 5501 | B63: AZ | C63: FM | D63: Fire | E63: BOULDER VIEW FIRE | F63: 45471 | G63: 45473 | H63: 45471 | I63: FALSE | J63: 1 | K63: 45535
A64: 5502 | B64: CA | C64: FM | D64: Fire | E64: THOMPSON FIRE | F64: 45475 | G64: 45479 | H64: 45475 | I64: FALSE | J64: 1 | K64: 45565
A65: 5503 | B65: CA | C65: FM | D65: Fire | E65: FRENCH FIRE | F65: 45477 | G65: 45480 | H65: 45478 | I65: FALSE | J65: 1 | K65: 45565
A66: 4798 | B66: TX | C66: DR | D66: Hurricane | E66: HURRICANE BERYL | F66: 45478 | G66: 45482 | H66: 45482 | I66: FALSE | J66: 67 | K66: 45565
...

Sheet Legend
A2: AEP | B2: Equals 1 during the Annual Enrollment Period (Oct 15 - Dec 7 each year). Row highlights blue. | C2: Anyone with medicare change/switch between Original Medicare and Medicare Advantage, or alter prescription drug plans.
A3: MA_OEP | B3: Equals 1 during the Medicare Advantage Open Enrollment Period (Jan 1 - Mar 31 each year). Row highlights green. | C3: For individuals already in a Medicare Advantage plan, allows single change to switch to other Medicare Advantage plan or return to Original Medicare.
A4: GEP | B4: Equals 1 during General Enrollment Period, Same as MA_OEP, same column. Row highlights green. | C4: For individuals who missed their Initial Enrollment Period when first elligible, allowing to sign up for Part A and/or Part B.
A5: SEP_Notes | B5: Use for date-bound SEPs (e.g., disaster SEPs by state). Most SEPs are triggered by individual circumstances, not calendar dates. | C5: For individuals with special life events to outside standard windows.
A6: Has_Event / Event_Detail | B6: Counts and pulls the matching row from the Events tab automatically. Row highlights orange when an event lands on that date. If two events share a date, Event_Detail shows only the first - prefer one combined row per date on the Events tab.
A8: Events tab | B8: One row per policy/market event.
A9: Date_Type | B9: Announced' = the day the rule/notice was published (matters for market/search reaction). 'Effective' = the day the policy actually changes plan value.
A11: Color key | B11: Orange = policy event day | Blue = AEP | Green = MA OEP / GEP | Yellow = cells you edit
