Workbook

Sheet Daily Grid
A1: Date | B1: Year | C1: Month | D1: Weekday | E1: AEP | F1: MA_OEP / GEP | G1: SEP_Notes | H1: Has_Event | I1: Event_Detail
A2: 45292 | B2: =YEAR($A2) -> 2024 | C2: =MONTH($A2) -> 1 | D2: =TEXT($A2,"ddd") -> Mon | E2: =IF(OR(AND(MONTH($A2)=10,DAY($A2)>=15),MONTH($A2)=11,AND(MONTH($A2)=12,DAY($A2)<=7)),1,0) -> 0 | F2: =IF(MONTH($A2)<=3,1,0) -> 1 | G2: {=_xlfn.TEXTJOIN(" | ",TRUE(),IF('FEMA Disasters'!$F$2:$F$1000=$A2,'FEMA Disasters'!$D$2:$D$1000&" begin: ["&'FEMA Disasters'!$B$2:$B$1000&"] "&'FEMA Disasters'!$C$2:$C$1000&"-"&'FEMA Disasters'!$A$2:$A$1000,""),IF('FEMA Disasters'!$G$2:$G$1000=$A2,'FEMA Disasters'!$D$2:$D$1000&" ended: ["&'FEMA Disasters'!$B$2:$B$1000&"] "&'FEMA Disasters'!$C$2:$C$1000&"-"&'FEMA Disasters'!$A$2:$A$1000,""),IF('FEMA Disasters'!$K$2:$K$1000=$A2,"Disaster SEP opens: "&'FEMA Disasters'!$D$2:$D$1000&" ["&'FEMA Disasters'!$B$2:$B$1000&"] "&'FEMA Disasters'!$C$2:$C$1000&"-"&'FEMA Disasters'!$A$2:$A$1000,""),IF('FEMA Disasters'!$L$2:$L$1000=$A2,"Disaster SEP ended: "&'FEMA Disasters'!$D$2:$D$1000&" ["&'FEMA Disasters'!$B$2:$B$1000&"] "&'FEMA Disasters'!$C$2:$C$1000&"-"&'FEMA Disasters'!$A$2:$A$1000,""))} | H2: =COUNTIF(Events!$A$2:$A$397,$A2) -> 2 | I2: {=_xlfn.TEXTJOIN(" | ",TRUE(),IF(Events!$A$2:$A$397=$A2,Events!$E$2:$E$397&IF(Events!$G$2:$G$397="National",""," ["&Events!$G$2:$G$397&"]"),""))} -> IRA phase-in: 5% coinsurance in Part D catastrophic phase eliminated; full Low-Income Subsidy (Extra Help) expanded to 150% FPL | Kentucky Medigap birthday rule takes effect (2023 HB 345, Ch. 182; KRS 304.14-525): enrollees may switch to another insurer's same-letter policy within 60 days after their birthday, no medical underwriting; law also added under-65 open enrollment protections [KY]
A3: 45293 | B3: =YEAR($A3) -> 2024 | C3: =MONTH($A3) -> 1 | D3: =TEXT($A3,"ddd") -> Tue | E3: =IF(OR(AND(MONTH($A3)=10,DAY($A3)>=15),MONTH($A3)=11,AND(MONTH($A3)=12,DAY($A3)<=7)),1,0) -> 0 | F3: =IF(MONTH($A3)<=3,1,0) -> 1 | G3: {=_xlfn.TEXTJOIN(" | ",TRUE(),IF('FEMA Disasters'!$F$2:$F$1000=$A3,'FEMA Disasters'!$D$2:$D$1000&" begin: ["&'FEMA Disasters'!$B$2:$B$1000&"] "&'FEMA Disasters'!$C$2:$C$1000&"-"&'FEMA Disasters'!$A$2:$A$1000,""),IF('FEMA Disasters'!$G$2:$G$1000=$A3,'FEMA Disasters'!$D$2:$D$1000&" ended: ["&'FEMA Disasters'!$B$2:$B$1000&"] "&'FEMA Disasters'!$C$2:$C$1000&"-"&'FEMA Disasters'!$A$2:$A$1000,""),IF('FEMA Disasters'!$K$2:$K$1000=$A3,"Disaster SEP opens: "&'FEMA Disasters'!$D$2:$D$1000&" ["&'FEMA Disasters'!$B$2:$B$1000&"] "&'FEMA Disasters'!$C$2:$C$1000&"-"&'FEMA Disasters'!$A$2:$A$1000,""),IF('FEMA Disasters'!$L$2:$L$1000=$A3,"Disaster SEP ended: "&'FEMA Disasters'!$D$2:$D$1000&" ["&'FEMA Disasters'!$B$2:$B$1000&"] "&'FEMA Disasters'!$C$2:$C$1000&"-"&'FEMA Disasters'!$A$2:$A$1000,""))} | H3: =COUNTIF(Events!$A$2:$A$397,$A3) -> 0 | I3: {=_xlfn.TEXTJOIN(" | ",TRUE(),IF(Events!$A$2:$A$397=$A3,Events!$E$2:$E$397&IF(Events!$G$2:$G$397="National",""," ["&Events!$G$2:$G$397&"]"),""))}
A4: 45294 | B4: =YEAR($A4) -> 2024 | C4: =MONTH($A4) -> 1 | D4: =TEXT($A4,"ddd") -> Wed | E4: =IF(OR(AND(MONTH($A4)=10,DAY($A4)>=15),MONTH($A4)=11,AND(MONTH($A4)=12,DAY($A4)<=7)),1,0) -> 0 | F4: =IF(MONTH($A4)<=3,1,0) -> 1 | G4: {=_xlfn.TEXTJOIN(" | ",TRUE(),IF('FEMA Disasters'!$F$2:$F$1000=$A4,'FEMA Disasters'!$D$2:$D$1000&" begin: ["&'FEMA Disasters'!$B$2:$B$1000&"] "&'FEMA Disasters'!$C$2:$C$1000&"-"&'FEMA Disasters'!$A$2:$A$1000,""),IF('FEMA Disasters'!$G$2:$G$1000=$A4,'FEMA Disasters'!$D$2:$D$1000&" ended: ["&'FEMA Disasters'!$B$2:$B$1000&"] "&'FEMA Disasters'!$C$2:$C$1000&"-"&'FEMA Disasters'!$A$2:$A$1000,""),IF('FEMA Disasters'!$K$2:$K$1000=$A4,"Disaster SEP opens: "&'FEMA Disasters'!$D$2:$D$1000&" ["&'FEMA Disasters'!$B$2:$B$1000&"] "&'FEMA Disasters'!$C$2:$C$1000&"-"&'FEMA Disasters'!$A$2:$A$1000,""),IF('FEMA Disasters'!$L$2:$L$1000=$A4,"Disaster SEP ended: "&'FEMA Disasters'!$D$2:$D$1000&" ["&'FEMA Disasters'!$B$2:$B$1000&"] "&'FEMA Disasters'!$C$2:$C$1000&"-"&'FEMA Disasters'!$A$2:$A$1000,""))} | H4: =COUNTIF(Events!$A$2:$A$397,$A4) -> 0 | I4: {=_xlfn.TEXTJOIN(" | ",TRUE(),IF(Events!$A$2:$A$397=$A4,Events!$E$2:$E$397&IF(Events!$G$2:$G$397="National",""," ["&Events!$G$2:$G$397&"]"),""))}
A5: 45295 | B5: =YEAR($A5) -> 2024 | C5: =MONTH($A5) -> 1 | D5: =TEXT($A5,"ddd") -> Thu | E5: =IF(OR(AND(MONTH($A5)=10,DAY($A5)>=15),MONTH($A5)=11,AND(MONTH($A5)=12,DAY($A5)<=7)),1,0) -> 0 | F5: =IF(MONTH($A5)<=3,1,0) -> 1 | G5: {=_xlfn.TEXTJOIN(" | ",TRUE(),IF('FEMA Disasters'!$F$2:$F$1000=$A5,'FEMA Disasters'!$D$2:$D$1000&" begin: ["&'FEMA Disasters'!$B$2:$B$1000&"] "&'FEMA Disasters'!$C$2:$C$1000&"-"&'FEMA Disasters'!$A$2:$A$1000,""),IF('FEMA Disasters'!$G$2:$G$1000=$A5,'FEMA Disasters'!$D$2:$D$1000&" ended: ["&'FEMA Disasters'!$B$2:$B$1000&"] "&'FEMA Disasters'!$C$2:$C$1000&"-"&'FEMA Disasters'!$A$2:$A$1000,""),IF('FEMA Disasters'!$K$2:$K$1000=$A5,"Disaster SEP opens: "&'FEMA Disasters'!$D$2:$D$1000&" ["&'FEMA Disasters'!$B$2:$B$1000&"] "&'FEMA Disasters'!$C$2:$C$1000&"-"&'FEMA Disasters'!$A$2:$A$1000,""),IF('FEMA Disasters'!$L$2:$L$1000=$A5,"Disaster SEP ended: "&'FEMA Disasters'!$D$2:$D$1000&" ["&'FEMA Disasters'!$B$2:$B$1000&"] "&'FEMA Disasters'!$C$2:$C$1000&"-"&'FEMA Disasters'!$A$2:$A$1000,""))} | H5: =COUNTIF(Events!$A$2:$A$397,$A5) -> 0 | I5: {=_xlfn.TEXTJOIN(" | ",TRUE(),IF(Events!$A$2:$A$397=$A5,Events!$E$2:$E$397&IF(Events!$G$2:$G$397="National",""," ["&Events!$G$2:$G$397&"]"),""))}
A6: 45296 | B6: =YEAR($A6) -> 2024 | C6: =MONTH($A6) -> 1 | D6: =TEXT($A6,"ddd") -> Fri | E6: =IF(OR(AND(MONTH($A6)=10,DAY($A6)>=15),MONTH($A6)=11,AND(MONTH($A6)=12,DAY($A6)<=7)),1,0) -> 0 | F6: =IF(MONTH($A6)<=3,1,0) -> 1 | G6: {=_xlfn.TEXTJOIN(" | ",TRUE(),IF('FEMA Disasters'!$F$2:$F$1000=$A6,'FEMA Disasters'!$D$2:$D$1000&" begin: ["&'FEMA Disasters'!$B$2:$B$1000&"] "&'FEMA Disasters'!$C$2:$C$1000&"-"&'FEMA Disasters'!$A$2:$A$1000,""),IF('FEMA Disasters'!$G$2:$G$1000=$A6,'FEMA Disasters'!$D$2:$D$1000&" ended: ["&'FEMA Disasters'!$B$2:$B$1000&"] "&'FEMA Disasters'!$C$2:$C$1000&"-"&'FEMA Disasters'!$A$2:$A$1000,""),IF('FEMA Disasters'!$K$2:$K$1000=$A6,"Disaster SEP opens: "&'FEMA Disasters'!$D$2:$D$1000&" ["&'FEMA Disasters'!$B$2:$B$1000&"] "&'FEMA Disasters'!$C$2:$C$1000&"-"&'FEMA Disasters'!$A$2:$A$1000,""),IF('FEMA Disasters'!$L$2:$L$1000=$A6,"Disaster SEP ended: "&'FEMA Disasters'!$D$2:$D$1000&" ["&'FEMA Disasters'!$B$2:$B$1000&"] "&'FEMA Disasters'!$C$2:$C$1000&"-"&'FEMA Disasters'!$A$2:$A$1000,""))} -> Severe Storm begin: [WA] DR-4775 | Disaster SEP opens: Severe Storm [WA] DR-4775 | H6: =COUNTIF(Events!$A$2:$A$397,$A6) -> 0 | I6: {=_xlfn.TEXTJOIN(" | ",TRUE(),IF(Events!$A$2:$A$397=$A6,Events!$E$2:$E$397&IF(Events!$G$2:$G$397="National",""," ["&Events!$G$2:$G$397&"]"),""))}
A7: 45297 | B7: =YEAR($A7) -> 2024 | C7: =MONTH($A7) -> 1 | D7: =TEXT($A7,"ddd") -> Sat | E7: =IF(OR(AND(MONTH($A7)=10,DAY($A7)>=15),MONTH($A7)=11,AND(MONTH($A7)=12,DAY($A7)<=7)),1,0) -> 0 | F7: =IF(MONTH($A7)<=3,1,0) -> 1 | G7: {=_xlfn.TEXTJOIN(" | ",TRUE(),IF('FEMA Disasters'!$F$2:$F$1000=$A7,'FEMA Disasters'!$D$2:$D$1000&" begin: ["&'FEMA Disasters'!$B$2:$B$1000&"] "&'FEMA Disasters'!$C$2:$C$1000&"-"&'FEMA Disasters'!$A$2:$A$1000,""),IF('FEMA Disasters'!$G$2:$G$1000=$A7,'FEMA Disasters'!$D$2:$D$1000&" ended: ["&'FEMA Disasters'!$B$2:$B$1000&"] "&'FEMA Disasters'!$C$2:$C$1000&"-"&'FEMA Disasters'!$A$2:$A$1000,""),IF('FEMA Disasters'!$K$2:$K$1000=$A7,"Disaster SEP opens: "&'FEMA Disasters'!$D$2:$D$1000&" ["&'FEMA Disasters'!$B$2:$B$1000&"] "&'FEMA Disasters'!$C$2:$C$1000&"-"&'FEMA Disasters'!$A$2:$A$1000,""),IF('FEMA Disasters'!$L$2:$L$1000=$A7,"Disaster SEP ended: "&'FEMA Disasters'!$D$2:$D$1000&" ["&'FEMA Disasters'!$B$2:$B$1000&"] "&'FEMA Disasters'!$C$2:$C$1000&"-"&'FEMA Disasters'!$A$2:$A$1000,""))} | H7: =COUNTIF(Events!$A$2:$A$397,$A7) -> 0 | I7: {=_xlfn.TEXTJOIN(" | ",TRUE(),IF(Events!$A$2:$A$397=$A7,Events!$E$2:$E$397&IF(Events!$G$2:$G$397="National",""," ["&Events!$G$2:$G$397&"]"),""))}
A8: 45298 | B8: =YEAR($A8) -> 2024 | C8: =MONTH($A8) -> 1 | D8: =TEXT($A8,"ddd") -> Sun | E8: =IF(OR(AND(MONTH($A8)=10,DAY($A8)>=15),MONTH($A8)=11,AND(MONTH($A8)=12,DAY($A8)<=7)),1,0) -> 0 | F8: =IF(MONTH($A8)<=3,1,0) -> 1 | G8: {=_xlfn.TEXTJOIN(" | ",TRUE(),IF('FEMA Disasters'!$F$2:$F$1000=$A8,'FEMA Disasters'!$D$2:$D$1000&" begin: ["&'FEMA Disasters'!$B$2:$B$1000&"] "&'FEMA Disasters'!$C$2:$C$1000&"-"&'FEMA Disasters'!$A$2:$A$1000,""),IF('FEMA Disasters'!$G$2:$G$1000=$A8,'FEMA Disasters'!$D$2:$D$1000&" ended: ["&'FEMA Disasters'!$B$2:$B$1000&"] "&'FEMA Disasters'!$C$2:$C$1000&"-"&'FEMA Disasters'!$A$2:$A$1000,""),IF('FEMA Disasters'!$K$2:$K$1000=$A8,"Disaster SEP opens: "&'FEMA Disasters'!$D$2:$D$1000&" ["&'FEMA Disasters'!$B$2:$B$1000&"] "&'FEMA Disasters'!$C$2:$C$1000&"-"&'FEMA Disasters'!$A$2:$A$1000,""),IF('FEMA Disasters'!$L$2:$L$1000=$A8,"Disaster SEP ended: "&'FEMA Disasters'!$D$2:$D$1000&" ["&'FEMA Disasters'!$B$2:$B$1000&"] "&'FEMA Disasters'!$C$2:$C$1000&"-"&'FEMA Disasters'!$A$2:$A$1000,""))} | H8: =COUNTIF(Events!$A$2:$A$397,$A8) -> 0 | I8: {=_xlfn.TEXTJOIN(" | ",TRUE(),IF(Events!$A$2:$A$397=$A8,Events!$E$2:$E$397&IF(Events!$G$2:$G$397="National",""," ["&Events!$G$2:$G$397&"]"),""))}
A9: 45299 | B9: =YEAR($A9) -> 2024 | C9: =MONTH($A9) -> 1 | D9: =TEXT($A9,"ddd") -> Mon | E9: =IF(OR(AND(MONTH($A9)=10,DAY($A9)>=15),MONTH($A9)=11,AND(MONTH($A9)=12,DAY($A9)<=7)),1,0) -> 0 | F9: =IF(MONTH($A9)<=3,1,0) -> 1 | G9: {=_xlfn.TEXTJOIN(" | ",TRUE(),IF('FEMA Disasters'!$F$2:$F$1000=$A9,'FEMA Disasters'!$D$2:$D$1000&" begin: ["&'FEMA Disasters'!$B$2:$B$1000&"] "&'FEMA Disasters'!$C$2:$C$1000&"-"&'FEMA Disasters'!$A$2:$A$1000,""),IF('FEMA Disasters'!$G$2:$G$1000=$A9,'FEMA Disasters'!$D$2:$D$1000&" ended: ["&'FEMA Disasters'!$B$2:$B$1000&"] "&'FEMA Disasters'!$C$2:$C$1000&"-"&'FEMA Disasters'!$A$2:$A$1000,""),IF('FEMA Disasters'!$K$2:$K$1000=$A9,"Disaster SEP opens: "&'FEMA Disasters'!$D$2:$D$1000&" ["&'FEMA Disasters'!$B$2:$B$1000&"] "&'FEMA Disasters'!$C$2:$C$1000&"-"&'FEMA Disasters'!$A$2:$A$1000,""),IF('FEMA Disasters'!$L$2:$L$1000=$A9,"Disaster SEP ended: "&'FEMA Disasters'!$D$2:$D$1000&" ["&'FEMA Disasters'!$B$2:$B$1000&"] "&'FEMA Disasters'!$C$2:$C$1000&"-"&'FEMA Disasters'!$A$2:$A$1000,""))} -> Winter Storm begin: [KS] DR-4774 | Disaster SEP opens: Winter Storm [KS] DR-4774 | H9: =COUNTIF(Events!$A$2:$A$397,$A9) -> 0 | I9: {=_xlfn.TEXTJOIN(" | ",TRUE(),IF(Events!$A$2:$A$397=$A9,Events!$E$2:$E$397&IF(Events!$G$2:$G$397="National",""," ["&Events!$G$2:$G$397&"]"),""))}
A10: 45300 | B10: =YEAR($A10) -> 2024 | C10: =MONTH($A10) -> 1 | D10: =TEXT($A10,"ddd") -> Tue | E10: =IF(OR(AND(MONTH($A10)=10,DAY($A10)>=15),MONTH($A10)=11,AND(MONTH($A10)=12,DAY($A10)<=7)),1,0) -> 0 | F10: =IF(MONTH($A10)<=3,1,0) -> 1 | G10: {=_xlfn.TEXTJOIN(" | ",TRUE(),IF('FEMA Disasters'!$F$2:$F$1000=$A10,'FEMA Disasters'!$D$2:$D$1000&" begin: ["&'FEMA Disasters'!$B$2:$B$1000&"] "&'FEMA Disasters'!$C$2:$C$1000&"-"&'FEMA Disasters'!$A$2:$A$1000,""),IF('FEMA Disasters'!$G$2:$G$1000=$A10,'FEMA Disasters'!$D$2:$D$1000&" ended: ["&'FEMA Disasters'!$B$2:$B$1000&"] "&'FEMA Disasters'!$C$2:$C$1000&"-"&'FEMA Disasters'!$A$2:$A$1000,""),IF('FEMA Disasters'!$K$2:$K$1000=$A10,"Disaster SEP opens: "&'FEMA Disasters'!$D$2:$D$1000&" ["&'FEMA Disasters'!$B$2:$B$1000&"] "&'FEMA Disasters'!$C$2:$C$1000&"-"&'FEMA Disasters'!$A$2:$A$1000,""),IF('FEMA Disasters'!$L$2:$L$1000=$A10,"Disaster SEP ended: "&'FEMA Disasters'!$D$2:$D$1000&" ["&'FEMA Disasters'!$B$2:$B$1000&"] "&'FEMA Disasters'!$C$2:$C$1000&"-"&'FEMA Disasters'!$A$2:$A$1000,""))} -> Severe Storm begin: [ME] DR-4764 | Severe Storm begin: [RI] DR-4766 | Severe Storm begin: [VT] DR-4770 | Severe Storm begin: [NH] DR-4771 | Disaster SEP opens: Severe Storm [ME] DR-4764 | Disaster SEP opens: Severe Storm [RI] DR-4766 | Disaster SEP opens: Severe Storm [VT] DR-4770 | Disaster SEP opens: Severe Storm [NH] DR-4771 | H10: =COUNTIF(Events!$A$2:$A$397,$A10) -> 0 | I10: {=_xlfn.TEXTJOIN(" | ",TRUE(),IF(Events!$A$2:$A$397=$A10,Events!$E$2:$E$397&IF(Events!$G$2:$G$397="National",""," ["&Events!$G$2:$G$397&"]"),""))}
A11: 45301 | B11: =YEAR($A11) -> 2024 | C11: =MONTH($A11) -> 1 | D11: =TEXT($A11,"ddd") -> Wed | E11: =IF(OR(AND(MONTH($A11)=10,DAY($A11)>=15),MONTH($A11)=11,AND(MONTH($A11)=12,DAY($A11)<=7)),1,0) -> 0 | F11: =IF(MONTH($A11)<=3,1,0) -> 1 | G11: {=_xlfn.TEXTJOIN(" | ",TRUE(),IF('FEMA Disasters'!$F$2:$F$1000=$A11,'FEMA Disasters'!$D$2:$D$1000&" begin: ["&'FEMA Disasters'!$B$2:$B$1000&"] "&'FEMA Disasters'!$C$2:$C$1000&"-"&'FEMA Disasters'!$A$2:$A$1000,""),IF('FEMA Disasters'!$G$2:$G$1000=$A11,'FEMA Disasters'!$D$2:$D$1000&" ended: ["&'FEMA Disasters'!$B$2:$B$1000&"] "&'FEMA Disasters'!$C$2:$C$1000&"-"&'FEMA Disasters'!$A$2:$A$1000,""),IF('FEMA Disasters'!$K$2:$K$1000=$A11,"Disaster SEP opens: "&'FEMA Disasters'!$D$2:$D$1000&" ["&'FEMA Disasters'!$B$2:$B$1000&"] "&'FEMA Disasters'!$C$2:$C$1000&"-"&'FEMA Disasters'!$A$2:$A$1000,""),IF('FEMA Disasters'!$L$2:$L$1000=$A11,"Disaster SEP ended: "&'FEMA Disasters'!$D$2:$D$1000&" ["&'FEMA Disasters'!$B$2:$B$1000&"] "&'FEMA Disasters'!$C$2:$C$1000&"-"&'FEMA Disasters'!$A$2:$A$1000,""))} -> Severe Storm begin: [CT] EM-3604 | Severe Storm begin: [OR] DR-4768 | Disaster SEP opens: Severe Storm [CT] EM-3604 | Disaster SEP opens: Severe Storm [OR] DR-4768 | H11: =COUNTIF(Events!$A$2:$A$397,$A11) -> 0 | I11: {=_xlfn.TEXTJOIN(" | ",TRUE(),IF(Events!$A$2:$A$397=$A11,Events!$E$2:$E$397&IF(Events!$G$2:$G$397="National",""," ["&Events!$G$2:$G$397&"]"),""))}
A12: 45302 | B12: =YEAR($A12) -> 2024 | C12: =MONTH($A12) -> 1 | D12: =TEXT($A12,"ddd") -> Thu | E12: =IF(OR(AND(MONTH($A12)=10,DAY($A12)>=15),MONTH($A12)=11,AND(MONTH($A12)=12,DAY($A12)<=7)),1,0) -> 0 | F12: =IF(MONTH($A12)<=3,1,0) -> 1 | G12: {=_xlfn.TEXTJOIN(" | ",TRUE(),IF('FEMA Disasters'!$F$2:$F$1000=$A12,'FEMA Disasters'!$D$2:$D$1000&" begin: ["&'FEMA Disasters'!$B$2:$B$1000&"] "&'FEMA Disasters'!$C$2:$C$1000&"-"&'FEMA Disasters'!$A$2:$A$1000,""),IF('FEMA Disasters'!$G$2:$G$1000=$A12,'FEMA Disasters'!$D$2:$D$1000&" ended: ["&'FEMA Disasters'!$B$2:$B$1000&"] "&'FEMA Disasters'!$C$2:$C$1000&"-"&'FEMA Disasters'!$A$2:$A$1000,""),IF('FEMA Disasters'!$K$2:$K$1000=$A12,"Disaster SEP opens: "&'FEMA Disasters'!$D$2:$D$1000&" ["&'FEMA Disasters'!$B$2:$B$1000&"] "&'FEMA Disasters'!$C$2:$C$1000&"-"&'FEMA Disasters'!$A$2:$A$1000,""),IF('FEMA Disasters'!$L$2:$L$1000=$A12,"Disaster SEP ended: "&'FEMA Disasters'!$D$2:$D$1000&" ["&'FEMA Disasters'!$B$2:$B$1000&"] "&'FEMA Disasters'!$C$2:$C$1000&"-"&'FEMA Disasters'!$A$2:$A$1000,""))} | H12: =COUNTIF(Events!$A$2:$A$397,$A12) -> 0 | I12: {=_xlfn.TEXTJOIN(" | ",TRUE(),IF(Events!$A$2:$A$397=$A12,Events!$E$2:$E$397&IF(Events!$G$2:$G$397="National",""," ["&Events!$G$2:$G$397&"]"),""))}
A13: 45303 | B13: =YEAR($A13) -> 2024 | C13: =MONTH($A13) -> 1 | D13: =TEXT($A13,"ddd") -> Fri | E13: =IF(OR(AND(MONTH($A13)=10,DAY($A13)>=15),MONTH($A13)=11,AND(MONTH($A13)=12,DAY($A13)<=7)),1,0) -> 0 | F13: =IF(MONTH($A13)<=3,1,0) -> 1 | G13: {=_xlfn.TEXTJOIN(" | ",TRUE(),IF('FEMA Disasters'!$F$2:$F$1000=$A13,'FEMA Disasters'!$D$2:$D$1000&" begin: ["&'FEMA Disasters'!$B$2:$B$1000&"] "&'FEMA Disasters'!$C$2:$C$1000&"-"&'FEMA Disasters'!$A$2:$A$1000,""),IF('FEMA Disasters'!$G$2:$G$1000=$A13,'FEMA Disasters'!$D$2:$D$1000&" ended: ["&'FEMA Disasters'!$B$2:$B$1000&"] "&'FEMA Disasters'!$C$2:$C$1000&"-"&'FEMA Disasters'!$A$2:$A$1000,""),IF('FEMA Disasters'!$K$2:$K$1000=$A13,"Disaster SEP opens: "&'FEMA Disasters'!$D$2:$D$1000&" ["&'FEMA Disasters'!$B$2:$B$1000&"] "&'FEMA Disasters'!$C$2:$C$1000&"-"&'FEMA Disasters'!$A$2:$A$1000,""),IF('FEMA Disasters'!$L$2:$L$1000=$A13,"Disaster SEP ended: "&'FEMA Disasters'!$D$2:$D$1000&" ["&'FEMA Disasters'!$B$2:$B$1000&"] "&'FEMA Disasters'!$C$2:$C$1000&"-"&'FEMA Disasters'!$A$2:$A$1000,""))} | H13: =COUNTIF(Events!$A$2:$A$397,$A13) -> 0 | I13: {=_xlfn.TEXTJOIN(" | ",TRUE(),IF(Events!$A$2:$A$397=$A13,Events!$E$2:$E$397&IF(Events!$G$2:$G$397="National",""," ["&Events!$G$2:$G$397&"]"),""))}
... A883: 46173 | B883: =YEAR($A883) -> 2026 | C883: =MONTH($A883) -> 5 | D883: =TEXT($A883,"ddd") -> Sun | E883: =IF(OR(AND(MONTH($A883)=10,DAY($A883)>=15),MONTH($A883)=11,AND(MONTH($A883)=12,DAY($A883)<=7)),1,0) -> 0 | F883: =IF(MONTH($A883)<=3,1,0) -> 0 | G883: {=_xlfn.TEXTJOIN(" | ",TRUE(),IF('FEMA Disasters'!$F$2:$F$1000=$A883,'FEMA Disasters'!$D$2:$D$1000&" begin: ["&'FEMA Disasters'!$B$2:$B$1000&"] "&'FEMA Disasters'!$C$2:$C$1000&"-"&'FEMA Disasters'!$A$2:$A$1000,""),IF('FEMA Disasters'!$G$2:$G$1000=$A883,'FEMA Disasters'!$D$2:$D$1000&" ended: ["&'FEMA Disasters'!$B$2:$B$1000&"] "&'FEMA Disasters'!$C$2:$C$1000&"-"&'FEMA Disasters'!$A$2:$A$1000,""),IF('FEMA Disasters'!$K$2:$K$1000=$A883,"Disaster SEP opens: "&'FEMA Disasters'!$D$2:$D$1000&" ["&'FEMA Disasters'!$B$2:$B$1000&"] "&'FEMA Disasters'!$C$2:$C$1000&"-"&'FEMA Disasters'!$A$2:$A$1000,""),IF('FEMA Disasters'!$L$2:$L$1000=$A883,"Disaster SEP ended: "&'FEMA Disasters'!$D$2:$D$1000&" ["&'FEMA Disasters'!$B$2:$B$1000&"] "&'FEMA Disasters'!$C$2:$C$1000&"-"&'FEMA Disasters'!$A$2:$A$1000,""))} -> Disaster SEP opens: Other [DC] EM-3643 | Disaster SEP opens: Flood [HI] DR-4909 | Disaster SEP opens: Severe Storm [ID] DR-4917 | Disaster SEP opens: Fire [NE] FM-5623 | Disaster SEP opens: Fire [OK] FM-5624 | Disaster SEP ended: Winter Storm [SC] EM-3632 | Disaster SEP ended: Winter Storm [NC] EM-3637 | Disaster SEP ended: Winter Storm [SC] DR-4908 | Disaster SEP ended: Winter Storm [VA] EM-3631 | Disaster SEP ended: Winter Storm [TN] EM-3635 | Disaster SEP ended: Winter Storm [GA] EM-3642 | Disaster SEP ended: Winter Storm [TN] DR-4898 | Disaster SEP ended: Winter Storm [KY] EM-3633 | Disaster SEP ended: Winter Storm [MD] EM-3634 | Disaster SEP ended: Winter Storm [AR] EM-3636 | Disaster SEP ended: Winter Storm [LA] EM-3638 | Disaster SEP ended: Winter Storm [WV] EM-3639 | Disaster SEP ended: Winter Storm [MS] EM-3640 | Disaster SEP ended: Winter Storm [IN] EM-3641 | Disaster SEP ended: Winter Storm [MS] DR-4899 | Disaster SEP ended: Winter Storm [LA] DR-4900 | Disaster SEP ended: Winter Storm [KY] DR-4913 | H883: =COUNTIF(Events!$A$2:$A$397,$A883) -> 0 | I883: {=_xlfn.TEXTJOIN(" | ",TRUE(),IF(Events!$A$2:$A$397=$A883,Events!$E$2:$E$397&IF(Events!$G$2:$G$397="National",""," ["&Events!$G$2:$G$397&"]"),""))}

Sheet Events
A1: Date | B1: Event_Type | C1: Affects | D1: Date_Type | E1: Description | F1: Source | G1: States | H1: Value_Mechanism
A2: 45292 | B2: Legislation | C2: Part D | D2: Effective | E2: IRA phase-in: 5% coinsurance in Part D catastrophic phase eliminated; full Low-Income Subsidy (Extra Help) expanded to 150% FPL | F2: https://www.cms.gov/newsroom/fact-sheets/2024-medicare-advantage-and-part-d-final-rule-cms-4201-f | G2: National | H2: Benefit/Cost Value
A3: 45292 | B3: State Regulation | C3: MS | D3: Effective | E3: Kentucky Medigap birthday rule takes effect (2023 HB 345, Ch. 182; KRS 304.14-525): enrollees may switch to another insurer's same-letter policy within 60 days after their birthday, no medical underwriting; law also added under-65 open enrollment protections | F3: https://insurance.ky.gov/ppc/Documents/2024.01.24%20Medicare%20Supplement%20Enrollment%20Changes.pdf | G3: KY | H3: Switching Window
A4: 45322 | B4: CMS Rule | C4: MA / Part D | D4: Announced | E4: CY2025 Advance Notice released: proposed +3.70% avg payment; year 2 of 3-year phase-in of 2024 CMS-HCC (V28) risk model at 67/33 blend; comments due 3/1/2024 | F4: https://www.cms.gov/newsroom/fact-sheets/2025-medicare-advantage-part-d-advance-notice-fact-sheet | G4: National | H4: Forward Signal
A5: 45383 | B5: Rate Announcement | C5: MA / Part D | D5: Announced | E5: CY2025 Rate Announcement: final MA capitation rates (+3.70% avg) and Part C/D payment policies | F5: https://www.cms.gov/newsroom/fact-sheets/2026-medicare-advantage-part-d-rate-announcement | G5: National | H5: Benefit/Cost Value
A6: 45386 | B6: CMS Rule | C6: MA / Part D / D-SNP / MS / C-SNP | D6: Announced | E6: CY2025 MA & Part D Final Rule (CMS-4205-F): fixed agent/broker compensation (+$100 initial), TPMO one-to-one consent for data sharing, mid-year unused-benefits notice, SSBCI evidence requirements, dual/LIS SEP overhaul, D-SNP look-alike threshold phase-down, behavioral health network adequacy || C-SNP: this rule created both main C-SNP push factors - the look-alike phase-down (70% for 2025, 60% for 2026) and the dual/LIS SEP overhaul - while C-SNPs are exempt from both. | F6: https://www.cms.gov/newsroom/fact-sheets/contract-year-2025-medicare-advantage-part-d-final-rule-cms-4205-f ; https://www.federalregister.gov/documents/2024/04/23/2024-07105/medicare-program-changes-to-the-medicare-advantage-and-the-medicare-prescription-drug-benefit | G6: National | H6: Plan Rules/Structure
A7: 45446 | B7: Litigation | C7: MA | D7: Announced | E7: D.D.C. rules for SCAN Health Plan: CMS's 2024 Star Ratings methodology (guardrail/Tukey sequencing) violated the APA; SCAN's rating ordered recalculated; Elevance won a parallel case ~6/11 | F7: https://www.scanhealthplan.com/about-scan/press-release-archive/scan-health-plan-prevails-in-2024-star-ratings-lawsuit-against-cms | G7: National | H7: Quality Ratings
A8: 45476 | B8: Litigation | C8: MA / MS | D8: Effective | E8: N.D. Tex. (Judge O'Connor) stays the CY2025 rule's broker fixed-compensation cap and FMO contract-term restrictions before AEP 2025 - these provisions of the 4/4/2024 final rule never took effect; broker steering incentives persisted (relative MA-vs-Medigap commission economics unchanged) | F8: https://www.fiercehealthcare.com/payers/court-stops-cms-broker-compensation-rule-medicare-advantage-plans | G8: National | H8: Distribution/Commission
A9: 45482 | B9: Litigation | C9: MA | D9: Effective | E9: Following SCAN/Elevance rulings, CMS recalculates 2024 Star Ratings industry-wide: 60+ plans across 40 insurers upgraded, ~$1.4B in additional quality bonus payments (date approximate - recalc rolled out late June/early July) | F9: https://www.beckerspayer.com/payer/unitedhealthcare-beats-cms-in-medicare-advantage-star-ratings/ | G9: National | H9: Quality Ratings
A10: 45519 | B10: Rate Announcement | C10: Part D | D10: Announced | E10: CMS publishes negotiated maximum fair prices (MFPs) for the first 10 Part D drugs (effective 1/1/2026) | F10: https://www.cms.gov/files/document/10522-inflation-reduction-act-timeline.pdf | G10: National | H10: Forward Signal
A11: 45565 | B11: Enrollment Milestone | C11: MA / Part D | D11: Deadline | E11: ANOC delivery deadline, the day enrollees are actually notified of their plan's CY2025 premium, benefit, and cost-sharing changes ahead of AEP. Synchronized mass-notification shock; CY2025 ANOCs carried the post-IRA changes ($2,000 OOP cap, Prescription Payment Plan, supplemental-benefit trims), making this the date the 2025 benefit-cut news reached consumers | F11: https://www.cms.gov/medicare/health-drug-plans/managed-care-marketing/models-standard-documents-educational-materials | G11: National | H11: Shopping Cycle
A12: 45566 | B12: Enrollment Milestone | C12: MA / Part D | D12: Effective | E12: CY2025 plan marketing begins; plan landscape/benefit info for 2025 released ahead of AEP; NOTE: the stayed fixed-compensation provisions did NOT apply - per CMS 7/18/2024 memo, pre-rule compensation regs governed AEP 2024; the $100/$50 administrative add-ons were removed from the CY2025 FMV amounts, leaving only the routine annual FMV update (~+2.3%), and administrative payments remained outside the compensation cap | F12: https://www.cms.gov/newsroom/fact-sheets/contract-year-2025-medicare-advantage-part-d-final-rule-cms-4205-f | G12: National | H12: Shopping Cycle
A13: 45575 | B13: Plan Landscape Release | C13: MA / Part D / MS | D13: Announced | E13: 2025 Star Ratings published on Medicare Plan Finder: sharp industry decline - only 7 MA-PD contracts earned 5 stars (vs 38 for 2024); avg rating fell to ~3.92; drives 2026 quality bonus payments | F13: https://www.cms.gov/newsroom/fact-sheets/2025-medicare-advantage-part-d-star-ratings | G13: National | H13: Quality Ratings
... A50: 46169 | B50: Litigation | C50: MA | D50: Announced | E50: Clover v. HHS: federal court in Georgia finds CMS improperly used two groups of 10 measures in calculating Clover's 2026 Star Rating - the ruling that triggered CMS's June 2026 industry-wide recalculation (recalc itself is post-window) | F50: https://www.healthcarefinancenews.com/news/scan-alignment-sue-cms-over-medicare-advantage-star-ratings | G50: National | H50: Quality Ratings

Sheet FEMA Disasters
A1: Disaster_Num | B1: State | C1: Decl_Type | D1: Incident_Type | E1: Title | F1: Incident_Begin | G1: Incident_End | H1: Declaration_Date | I1: IA_Declared | J1: Designated_Areas | K1: SEP_Start | L1: SEP_End
A2: 4775 | B2: WA | C2: DR | D2: Severe Storm | E2: SEVERE WINTER STORMS, STRAIGHT-LINE WINDS, FLOODING, LANDSLIDES, AND MUDSLIDES | F2: 45296 | G2: 45320 | H2: 45410 | I2: FALSE | J2: 17 | K2: =IF(OR(C2="DR",C2="EM"),MIN(F2,H2),"") -> 45296 | L2: =IF(K2="","",EOMONTH(K2,2)) -> 45382
A3: 4774 | B3: KS | C3: DR | D3: Winter Storm | E3: SEVERE WINTER STORM | F3: 45299 | G3: 45307 | H3: 45410 | I3: FALSE | J3: 17 | K3: =IF(OR(C3="DR",C3="EM"),MIN(F3,H3),"") -> 45299 | L3: =IF(K3="","",EOMONTH(K3,2)) -> 45382
A4: 4764 | B4: ME | C4: DR | D4: Severe Storm | E4: SEVERE STORMS AND FLOODING | F4: 45300 | G4: 45304 | H4: 45371 | I4: FALSE | J4: 8 | K4: =IF(OR(C4="DR",C4="EM"),MIN(F4,H4),"") -> 45300 | L4: =IF(K4="","",EOMONTH(K4,2)) -> 45382
A5: 4766 | B5: RI | C5: DR | D5: Severe Storm | E5: SEVERE STORMS AND FLOODING | F5: 45300 | G5: 45304 | H5: 45371 | I5: FALSE | J5: 4 | K5: =IF(OR(C5="DR",C5="EM"),MIN(F5,H5),"") -> 45300 | L5: =IF(K5="","",EOMONTH(K5,2)) -> 45382
A6: 4770 | B6: VT | C6: DR | D6: Severe Storm | E6: SEVERE WINTER STORM | F6: 45300 | G6: 45304 | H6: 45401 | I6: FALSE | J6: 5 | K6: =IF(OR(C6="DR",C6="EM"),MIN(F6,H6),"") -> 45300 | L6: =IF(K6="","",EOMONTH(K6,2)) -> 45382
A7: 4771 | B7: NH | C7: DR | D7: Severe Storm | E7: SEVERE STORMS AND FLOODING | F7: 45300 | G7: 45305 | H7: 45401 | I7: FALSE | J7: 2 | K7: =IF(OR(C7="DR",C7="EM"),MIN(F7,H7),"") -> 45300 | L7: =IF(K7="","",EOMONTH(K7,2)) -> 45382
A8: 3604 | B8: CT | C8: EM | D8: Severe Storm | E8: SEVERE STORMS, FLOODING, AND A POTENTIAL DAM BREACH | F8: 45301 | G8: 45304 | H8: 45304 | I8: FALSE | J8: 3 | K8: =IF(OR(C8="DR",C8="EM"),MIN(F8,H8),"") -> 45301 | L8: =IF(K8="","",EOMONTH(K8,2)) -> 45382
A9: 4768 | B9: OR | C9: DR | D9: Severe Storm | E9: SEVERE WINTER STORMS, STRAIGHT-LINE WINDS, LANDSLIDES, AND MUDSLIDES | F9: 45301 | G9: 45313 | H9: 45395 | I9: FALSE | J9: 13 | K9: =IF(OR(C9="DR",C9="EM"),MIN(F9,H9),"") -> 45301 | L9: =IF(K9="","",EOMONTH(K9,2)) -> 45382
A10: 4758 | B10: CA | C10: DR | D10: Flood | E10: SEVERE STORM AND FLOODING | F10: 45312 | G10: 45314 | H10: 45341 | I10: FALSE | J10: 1 | K10: =IF(OR(C10="DR",C10="EM"),MIN(F10,H10),"") -> 45312 | L10: =IF(K10="","",EOMONTH(K10,2)) -> 45382
A11: 4773 | B11: CA | C11: DR | D11: Severe Storm | E11: SEVERE WINTER STORM | F11: 45321 | G11: 45322 | H11: 45401 | I11: FALSE | J11: 1 | K11: =IF(OR(C11="DR",C11="EM"),MIN(F11,H11),"") -> 45321 | L11: =IF(K11="","",EOMONTH(K11,2)) -> 45382
A12: 4769 | B12: CA | C12: DR | D12: Severe Storm | E12: SEVERE WINTER STORMS, TORNADOES, FLOODING, LANDSLIDES, AND MUDSLIDES | F12: 45322 | G12: 45331 | H12: 45395 | I12: FALSE | J12: 9 | K12: =IF(OR(C12="DR",C12="EM"),MIN(F12,H12),"") -> 45322 | L12: =IF(K12="","",EOMONTH(K12,2)) -> 45382
A13: 4772 | B13: CA | C13: DR | D13: Severe Storm | E13: SEVERE STORMS AND FLOODING | F13: 45322 | G13: 45331 | H13: 45401 | I13: FALSE | J13: 1 | K13: =IF(OR(C13="DR",C13="EM"),MIN(F13,H13),"") -> 45322 | L13: =IF(K13="","",EOMONTH(K13,2)) -> 45382
... A38: 4794 | B38: FL | C38: DR | D38: Severe Storm | E38: SEVERE STORMS, STRAIGHT-LINE WINDS, AND TORNADOES | F38: 45422 | G38: 45422 | H38: 45460 | I38: FALSE | J38: 13 | K38: =IF(OR(C38="DR",C38="EM"),MIN(F38,H38),"") -> 45422 | L38: =IF(K38="","",EOMONTH(K38,2)) -> 45504
A39: 5492 | B39: NM | C39: FM | D39: Fire | E39: BLUE 2 FIRE | F39: 45428 | H39: 45438 | I39: FALSE | J39: 1 | L39: =IF(K39="","",EOMONTH(K39,2))
A40: 4791 | B40: OK | C40: DR | D40: Severe Storm | E40: SEVERE STORMS, STRAIGHT-LINE WINDS, TORNADOES, AND FLOODING | F40: 45431 | G40: 45440 | H40: 45457 | I40: FALSE | J40: 10 | K40: 45504 | L40: =IF(K40="","",EOMONTH(K40,2)) -> 45565
A41: 4803 | B41: MO | C41: DR | D41: Severe Storm | E41: SEVERE STORMS, STRAIGHT-LINE WINDS, TORNADOES, AND FLOODING | F41: 45431 | G41: 45439 | H41: 45496 | I41: FALSE | J41: 15 | K41: 45504 | L41: =IF(K41="","",EOMONTH(K41,2)) -> 45565
A42: 4811 | B42: KS | C42: DR | D42: Severe Storm | E42: SEVERE STORM, STRAIGHT-LINE WINDS, TORNADOES, AND FLOODING | F42: 45431 | G42: 45431 | H42: 45524 | I42: FALSE | J42: 14 | K42: 45504 | L42: =IF(K42="","",EOMONTH(K42,2)) -> 45565
A43: 4784 | B43: IA | C43: DR | D43: Severe Storm | E43: SEVERE STORMS, TORNADOES, AND FLOODING | F43: 45432 | G43: 45443 | H43: 45436 | I43: FALSE | J43: 29 | K43: 45504 | L43: =IF(K43="","",EOMONTH(K43,2)) -> 45565
A44: 4808 | B44: NE | C44: DR | D44: Severe Storm | E44: SEVERE STORMS, STRAIGHT-LINE WINDS, TORNADOES, AND FLOODING | F44: 45432 | G44: 45446 | H44: 45524 | I44: FALSE | J44: 19 | K44: 45535 | L44: =IF(K44="","",EOMONTH(K44,2)) -> 45596
A45: 4804 | B45: KY | C45: DR | D45: Severe Storm | E45: SEVERE STORMS, STRAIGHT-LINE WINDS, TORNADOES, LANDSLIDES, AND MUDSLIDES | F45: 45433 | G45: 45439 | H45: 45496 | I45: FALSE | J45: 58 | K45: 45504 | L45: =IF(K45="","",EOMONTH(K45,2)) -> 45565
A46: 4788 | B46: AR | C46: DR | D46: Severe Storm | E46: SEVERE STORMS, STRAIGHT-LINE WINDS, TORNADOES, AND FLOODING | F46: 45436 | G46: 45439 | H46: 45442 | I46: FALSE | J46: 11 | K46: 45504 | L46: =IF(K46="","",EOMONTH(K46,2)) -> 45565
A47: 5493 | B47: AZ | C47: FM | D47: Fire | E47: SIMMONS FIRE | F47: 45440 | G47: 45443 | H47: 45441 | I47: FALSE | J47: 1 | K47: 45504 | L47: =IF(K47="","",EOMONTH(K47,2)) -> 45565
A48: 5494 | B48: NV | C48: FM | D48: Fire | E48: TRAIL FIRE | F48: 45454 | G48: 45456 | H48: 45454 | I48: FALSE | J48: 1 | K48: 45535 | L48: =IF(K48="","",EOMONTH(K48,2)) -> 45596
A49: 5495 | B49: NV | C49: FM | D49: Fire | E49: SULLIVAN FIRE | F49: 45454 | G49: 45455 | H49: 45455 | I49: FALSE | J49: 1 | K49: 45535 | L49: =IF(K49="","",EOMONTH(K49,2)) -> 45596
A50: 5496 | B50: AZ | C50: FM | D50: Fire | E50: ROSE FIRE | F50: 45455 | G50: 45457 | H50: 45455 | I50: FALSE | J50: 1 | K50: 45535 | L50: =IF(K50="","",EOMONTH(K50,2)) -> 45596
A51: 4796 | B51: IA | C51: DR | D51: Severe Storm | E51: SEVERE STORMS, FLOODING, STRAIGHT-LINE WINDS, AND TORNADOES | F51: 45459 | G51: 45496 | H51: 45467 | I51: FALSE | J51: 29 | K51: 45565 | L51: =IF(K51="","",EOMONTH(K51,2)) -> 45626
... A54: 4795 | B54: NM | C54: DR | D54: Fire | E54: SOUTH FORK FIRE, SALT FIRE, AND FLOODING | F54: 45460 | G54: 45524 | H54: 45463 | I54: FALSE | J54: 5 | K54: 45596 | L54: =IF(K54="","",EOMONTH(K54,2)) -> 45657
A55: 5497 | B55: NM | C55: FM | D55: Fire | E55: SOUTH FORK FIRE | F55: 45460 | H55: 45460 | I55: FALSE | J55: 3 | L55: =IF(K55="","",EOMONTH(K55,2))
A56: 5498 | B56: NM | C56: FM | D56: Fire | E56: SALT FIRE | F56: 45460 | H56: 45461 | I56: FALSE | J56: 3 | L56: =IF(K56="","",EOMONTH(K56,2))
A57: 4822 | B57: NE | C57: DR | D57: Severe Storm | E57: SEVERE STORMS, STRAIGHT-LINE WINDS, TORNADOES, AND FLOODING | F57: 45462 | G57: 45481 | H57: 45559 | I57: FALSE | J57: 17 | K57: 45565 | L57: =IF(K57="","",EOMONTH(K57,2)) -> 45626
A58: 4809 | B58: NM | C58: DR | D58: Flood | E58: SEVERE STORMS AND FLOODING | F58: 45463 | G58: 45464 | H58: 45524 | I58: FALSE | J58: 1 | K58: 45535 | L58: =IF(K58="","",EOMONTH(K58,2)) -> 45596
A59: 4823 | B59: WA | C59: DR | D59: Fire | E59: WILDFIRES | F59: 45465 | G59: 45481 | H59: 45559 | I59: FALSE | J59: 1 | K59: 45565 | L59: =IF(K59="","",EOMONTH(K59,2)) -> 45626
A60: 5499 | B60: WA | C60: FM | D60: Fire | E60: SLIDE RANCH FIRE | F60: 45465 | G60: 45484 | H60: 45466 | I60: FALSE | J60: 2 | K60: 45565 | L60: =IF(K60="","",EOMONTH(K60,2)) -> 45626
A61: 5500 | B61: OR | C61: FM | D61: Fire | E61: DARLENE 3 FIRE | F61: 45468 | H61: 45468 | I61: FALSE | J61: 1 | L61: =IF(K61="","",EOMONTH(K61,2))
A62: 4824 | B62: KS | C62: DR | D62: Severe Storm | E62: SEVERE STORMS, STRAIGHT-LINE WINDS, TORNADOES, AND FLOODING | F62: 45469 | G62: 45480 | H62: 45559 | I62: FALSE | J62: 17 | K62: 45565 | L62: =IF(K62="","",EOMONTH(K62,2)) -> 45626
A63: 5501 | B63: AZ | C63: FM | D63: Fire | E63: BOULDER VIEW FIRE | F63: 45471 | G63: 45473 | H63: 45471 | I63: FALSE | J63: 1 | K63: 45535 | L63: =IF(K63="","",EOMONTH(K63,2)) -> 45596
A64: 5502 | B64: CA | C64: FM | D64: Fire | E64: THOMPSON FIRE | F64: 45475 | G64: 45479 | H64: 45475 | I64: FALSE | J64: 1 | K64: 45565 | L64: =IF(K64="","",EOMONTH(K64,2)) -> 45626
A65: 5503 | B65: CA | C65: FM | D65: Fire | E65: FRENCH FIRE | F65: 45477 | G65: 45480 | H65: 45478 | I65: FALSE | J65: 1 | K65: 45565 | L65: =IF(K65="","",EOMONTH(K65,2)) -> 45626
A66: 4798 | B66: TX | C66: DR | D66: Hurricane | E66: HURRICANE BERYL | F66: 45478 | G66: 45482 | H66: 45482 | I66: FALSE | J66: 67 | K66: 45565 | L66: =IF(K66="","",EOMONTH(K66,2)) -> 45626
...

Sheet Fed Register
A1: Doc_Number | B1: Type | C1: Pub_Date | D1: Effective_Date | E1: Match | F1: Matched_Keywords | G1: Title | H1: Abstract | I1: URL | J1: Full_Text_Scanned | K1: Priority | L1: Trim_Note
A2: 2023-28831 | B2: Notice | C2: 45293 | E2: 0 | G2: Medicare and Medicaid Programs; Application from the Community Health Accreditation Program (CHAP) for Continued Approval of Its Home Health Agency Accreditation Program | H2: This notice announces our decision to approve the Community Health Accreditation Program (CHAP) for continued recognition as a national accrediting organization for home health agencies (HHAs) that wish to participate in the Medicare or Medicaid programs. | I2: https://www.federalregister.gov/documents/2024/01/02/2023-28831/medicare-and-medicaid-programs-application-from-the-community-health-accreditation-program-chap-for | J2: Y
A3: 2024-00205 | B3: Notice | C3: 45300 | E3: 0 | G3: Medicaid and Children's Health Insurance Program (CHIP) Generic Information Collection Activities: Proposed Collection; Comment Request | H3: On May 28, 2010, the Office of Management and Budget (OMB) issued Paperwork Reduction Act (PRA) guidance related to the "generic" clearance process. Generally, this is an expedited process by which agencies may obtain OMB's approval of collection of information requests that are "usually voluntary, low-burden, and uncontroversial collections," do not raise any substantive or policy issues, and do not require policy or methodological review. The process requires the submission of an overarching p | I3: https://www.federalregister.gov/documents/2024/01/09/2024-00205/medicaid-and-childrens-health-insurance-program-chip-generic-information-collection-activities | J3: Y
A4: 2024-00270 | B4: Notice | C4: 45301 | E4: 0 | G4: Agency Information Collection Activities: Proposed Collection; Comment Request | H4: The Centers for Medicare & Medicaid Services (CMS) is announcing an opportunity for the public to comment on CMS' intention to collect information from the public. Under the Paperwork Reduction Act of 1995 (PRA), Federal agencies are required to publish notice in the Federal Register concerning each proposed collection of information (including each proposed extension or reinstatement of an existing collection of information) and to allow 60 days for public comment on the proposed action. Intere | I4: https://www.federalregister.gov/documents/2024/01/10/2024-00270/agency-information-collection-activities-proposed-collection-comment-request | J4: Y
A5: 2024-00474 | B5: Notice | C5: 45302 | E5: 1 | F5: part d(4); medicare advantage(1) | G5: Agency Information Collection Activities: Submission for OMB Review; Comment Request | H5: The Centers for Medicare & Medicaid Services (CMS) is announcing an opportunity for the public to comment on CMS' intention to collect information from the public. Under the Paperwork Reduction Act of 1995 (PRA), Federal agencies are required to publish notice in the Federal Register concerning each proposed collection of information, including each proposed extension or reinstatement of an existing collection of information, and to allow a second opportunity for public comment on the notice. In | I5: https://www.federalregister.gov/documents/2024/01/11/2024-00474/agency-information-collection-activities-submission-for-omb-review-comment-request | J5: Y | K5: SKIP | L5: PRA paperwork notice
A6: 2024-00657 | B6: Notice | C6: 45307 | E6: 1 | F6: dual eligible(3) | G6: Agency Information Collection Activities: Submission for OMB Review; Comment Request | H6: The Centers for Medicare & Medicaid Services (CMS) is announcing an opportunity for the public to comment on CMS' intention to collect information from the public. Under the Paperwork Reduction Act of 1995 (PRA), federal agencies are required to publish notice in the Federal Register concerning each proposed collection of information, including each proposed extension or reinstatement of an existing collection of information, and to allow a second opportunity for public comment on the notice. In | I6: https://www.federalregister.gov/documents/2024/01/16/2024-00657/agency-information-collection-activities-submission-for-omb-review-comment-request | J6: Y | K6: SKIP | L6: PRA paperwork notice
A7: 2024-00897 | B7: Notice | C7: 45309 | E7: 1 | F7: ma organization(6); part c(1) | G7: Agency Information Collection Activities: Submission for OMB Review; Comment Request | H7: The Centers for Medicare & Medicaid Services (CMS) is announcing an opportunity for the public to comment on CMS' intention to collect information from the public. Under the Paperwork Reduction Act of 1995 (PRA), federal agencies are required to publish notice in the Federal Register concerning each proposed collection of information, including each proposed extension or reinstatement of an existing collection of information, and to allow a second opportunity for public comment on the notice. In | I7: https://www.federalregister.gov/documents/2024/01/18/2024-00897/agency-information-collection-activities-submission-for-omb-review-comment-request | J7: Y | K7: SKIP | L7: PRA paperwork notice
A8: 2024-01072 | B8: Proposed Rule | C8: 45313 | D8: 45233 | E8: 0 | G8: Federal Independent Dispute Resolution Operations; Reopening of Comment Period | H8: This document reopens the comment period for the proposed rules entitled "Federal Independent Dispute Resolution Operations" that appeared in the November 3, 2023, issue of the Federal Register. The comment period for the proposed rules, which closed on January 2, 2024, is reopened from January 22, 2024 to February 5, 2024. | I8: https://www.federalregister.gov/documents/2024/01/22/2024-01072/federal-independent-dispute-resolution-operations-reopening-of-comment-period | J8: Y
A9: 2024-01383 | B9: Notice | C9: 45316 | E9: 1 | F9: medicare advantage(2) | G9: Agency Information Collection Activities: Submission for OMB Review; Comment Request | H9: The Centers for Medicare & Medicaid Services (CMS) is announcing an opportunity for the public to comment on CMS' intention to collect information from the public. Under the Paperwork Reduction Act of 1995 (PRA), Federal agencies are required to publish notice in the Federal Register concerning each proposed collection of information, including each proposed extension or reinstatement of an existing collection of information, and to allow a second opportunity for public comment on the notice. In | I9: https://www.federalregister.gov/documents/2024/01/25/2024-01383/agency-information-collection-activities-submission-for-omb-review-comment-request | J9: Y | K9: SKIP | L9: PRA paperwork notice
A10: 2024-01582 | B10: Notice | C10: 45317 | E10: 1 | F10: part d(8); medicare advantage(4); part c(2) | G10: Agency Information Collection Activities: Proposed Collection; Comment Request | H10: The Centers for Medicare & Medicaid Services (CMS) is announcing an opportunity for the public to comment on CMS' intention to collect information from the public. Under the Paperwork Reduction Act of 1995 (PRA), federal agencies are required to publish notice in the Federal Register concerning each proposed collection of information (including each proposed extension or reinstatement of an existing collection of information) and to allow 60 days for public comment on the proposed action. Intere | I10: https://www.federalregister.gov/documents/2024/01/26/2024-01582/agency-information-collection-activities-proposed-collection-comment-request | J10: Y | K10: SKIP | L10: PRA paperwork notice
A11: 2024-01723 | B11: Notice | C11: 45320 | E11: 1 | F11: part d(10) | G11: Agency Information Collection Activities: Proposed Collection; Comment Request | H11: The Centers for Medicare & Medicaid Services (CMS) is announcing an opportunity for the public to comment on CMS' intention to collect information from the public. Under the Paperwork Reduction Act of 1995 (PRA), Federal agencies are required to publish notice in the Federal Register concerning each proposed collection of information (including each proposed extension or reinstatement of an existing collection of information) and to allow 60 days for public comment on the proposed action. Intere | I11: https://www.federalregister.gov/documents/2024/01/29/2024-01723/agency-information-collection-activities-proposed-collection-comment-request | J11: Y | K11: SKIP | L11: PRA paperwork notice
A12: 2024-01785 | B12: Notice | C12: 45321 | E12: 1 | F12: medicare advantage(2); part d(1) | G12: Medicare and Medicaid Programs; Quarterly Listing of Program Issuances-October Through December 2023 | H12: This quarterly notice lists CMS manual instructions, substantive and interpretive regulations, and other Federal Register notices that were published in the 3-month period, relating to the Medicare and Medicaid programs and other programs administered by CMS. | I12: https://www.federalregister.gov/documents/2024/01/30/2024-01785/medicare-and-medicaid-programs-quarterly-listing-of-program-issuances-october-through-december-2023 | J12: Y | K12: SKIP | L12: catalog of issuances
A13: 2024-00895 | B13: Rule | C13: 45330 | D13: 45390 | E13: 1 | F13: ma organization(237); part d(26); medicare advantage(15); d-snp(11); part c(9); special needs plan(4); dual eligible(2) | G13: Medicare and Medicaid Programs; Patient Protection and Affordable Care Act; Advancing Interoperability and Improving Prior Authorization Processes for Medicare Advantage Organizations, Medicaid Managed Care Plans, State Medicaid Agencies, Children's Health Insurance Program (CHIP) Agencies and CHIP Managed Care Entities, Issuers of Qualified Health Plans on the Federally-Facilitated Exchanges, Merit-Based Incentive Payment System (MIPS) Eligible Clinicians, and Eligible Hospitals and Critical Access Hospitals in the Medicare Promoting Interoperability Program | H13: This final rule will improve the electronic exchange of health care data and streamline processes related to prior authorization through new requirements for Medicare Advantage (MA) organizations, state Medicaid fee-for-service (FFS) programs, state Children's Health Insurance Program (CHIP) FFS programs, Medicaid managed care plans, CHIP managed care entities, and Qualified Health Plan (QHP) issuers on the Federally-facilitated Exchanges (FFEs). This final rule will also add new measures for el | I13: https://www.federalregister.gov/documents/2024/02/08/2024-00895/medicare-and-medicaid-programs-patient-protection-and-affordable-care-act-advancing-interoperability | J13: Y | K13: HIGH | L13: core MA/Part D policy doc (strong kw=269)
A14: 2024-01094 | B14: Rule | C14: 45322 | D14: 45322 | E14: 0 | G14: Medicare Program; Calendar Year (CY) 2024 Home Health (HH) Prospective Payment System Rate Update; HH Quality Reporting Program Requirements; HH Value-Based Purchasing Expanded Model Requirements; Home Intravenous Immune Globulin Items and Services; Hospice Informal Dispute Resolution and Special Focus Program Requirements, Certain Requirements for Durable Medical Equipment Prosthetics and Orthotics Supplies; and Provider and Supplier Enrollment Requirements; Correction | H14: This document corrects technical errors in the final rule that appeared in the November 13, 2023 Federal Register titled "Medicare Program; Calendar Year (CY) 2024 Home Health (HH) Prospective Payment System Rate Update; HH Quality Reporting Program Requirements; HH Value-Based Purchasing Expanded Model Requirements; Home Intravenous Immune Globulin Items and Services; Hospice Informal Dispute Resolution and Special Focus Program Requirements, Certain Requirements for Durable Medical Equipment P | I14: https://www.federalregister.gov/documents/2024/01/31/2024-01094/medicare-program-calendar-year-cy-2024-home-health-hh-prospective-payment-system-rate-update-hh | J14: Y
A15: 2024-01831 | B15: Notice | C15: 45322 | E15: 0 | G15: Agency Information Collection Activities: Proposed Collection; Comment Request | H15: The Centers for Medicare & Medicaid Services (CMS) is announcing an opportunity for the public to comment on CMS' intention to collect information from the public. Under the Paperwork Reduction Act of 1995 (PRA), Federal agencies are required to publish notice in the Federal Register concerning each proposed collection of information (including each proposed extension or reinstatement of an existing collection of information) and to allow 60 days for public comment on the proposed action. Intere | I15: https://www.federalregister.gov/documents/2024/01/31/2024-01831/agency-information-collection-activities-proposed-collection-comment-request | J15: Y
A16: 2024-01942 | B16: Rule | C16: 45323 | D16: 45318 | E16: 0 | G16: Clinical Laboratory Improvement Amendments of 1988 (CLIA) Fees; Histocompatibility, Personnel, and Alternative Sanctions for Certificate of Waiver Laboratories; Correction | H16: This document corrects technical and typographical errors in the final rule that appeared in the December 28, 2023, Federal Register entitled, "Clinical Laboratory Improvement Amendments of 1988 (CLIA) Fees; Histocompatibility, Personnel, and Alternative Sanctions for Certificate of Waiver Laboratories" (referred to hereafter as the "December 2023 final rule"). | I16: https://www.federalregister.gov/documents/2024/02/01/2024-01942/clinical-laboratory-improvement-amendments-of-1988-clia-fees-histocompatibility-personnel-and | J16: Y
A17: 2024-02095 | B17: Notice | C17: 45324 | E17: 1 | F17: part d(5); part c(1) | G17: Agency Information Collection Activities: Proposed Collection; Comment Request | H17: The Centers for Medicare & Medicaid Services (CMS) is announcing an opportunity for the public to comment on CMS' intention to collect information from the public. Under the Paperwork Reduction Act of 1995 (PRA), Federal agencies are required to publish notice in the Federal Register concerning each proposed collection of information (including each proposed extension or reinstatement of an existing collection of information) and to allow 60 days for public comment on the proposed action. Intere | I17: https://www.federalregister.gov/documents/2024/02/02/2024-02095/agency-information-collection-activities-proposed-collection-comment-request | J17: Y | K17: SKIP | L17: PRA paperwork notice
A18: 2024-02243 | B18: Notice | C18: 45327 | E18: 0 | G18: Agency Information Collection Activities: Proposed Collection; Comment Request | H18: On May 28, 2010, the Office of Management and Budget (OMB) issued Paperwork Reduction Act (PRA) guidance related to the "generic" clearance process. Generally, this is an expedited clearance process by which agencies may obtain OMB's approval of collection of information requests that are "usually voluntary, low- burden, and uncontroversial," do not raise any substantive or policy issues, and do not require policy or methodological review. The process requires the submission of an overarching pl | I18: https://www.federalregister.gov/documents/2024/02/05/2024-02243/agency-information-collection-activities-proposed-collection-comment-request | J18: Y
A19: 2024-02306 | B19: Notice | C19: 45328 | E19: 1 | F19: ma organization(2) | G19: Agency Information Collection Activities: Submission for OMB Review; Comment Request | H19: The Centers for Medicare & Medicaid Services (CMS) is announcing an opportunity for the public to comment on CMS' intention to collect information from the public. Under the Paperwork Reduction Act of 1995 (PRA), Federal agencies are required to publish notice in the Federal Register concerning each proposed collection of information, including each proposed extension or reinstatement of an existing collection of information, and to allow a second opportunity for public comment on the notice. In | I19: https://www.federalregister.gov/documents/2024/02/06/2024-02306/agency-information-collection-activities-submission-for-omb-review-comment-request | J19: Y | K19: SKIP | L19: PRA paperwork notice
A20: 2024-02342 | B20: Notice | C20: 45328 | E20: 0 | G20: Medicare and Medicaid Programs; Application by DNV Healthcare USA Inc. (DNV) for Continued CMS Approval of Its Psychiatric Hospital Accreditation Program | H20: This proposed notice acknowledges the receipt of a deeming application from DNV Healthcare USA Inc. (DNV) for continued Centers for Medicare & Medicaid Services (CMS) approval of its psychiatric hospital accreditation program. The statute requires that within 60 days of receipt of an organization's complete application, CMS must publish a notice that identifies the national accrediting body making the request, describes the nature of the request, and provides at least a 30-day public comment per | I20: https://www.federalregister.gov/documents/2024/02/06/2024-02342/medicare-and-medicaid-programs-application-by-dnv-healthcare-usa-inc-dnv-for-continued-cms-approval | J20: Y
A21: 2024-02444 | B21: Notice | C21: 45329 | E21: 1 | F21: medicare advantage(2); part d(2) | G21: Agency Information Collection Activities: Proposed Collection; Comment Request | H21: The Centers for Medicare & Medicaid Services (CMS) is announcing an opportunity for the public to comment on CMS' intention to collect information from the public. Under the Paperwork Reduction Act of 1995 (PRA), federal agencies are required to publish notice in the Federal Register concerning each proposed collection of information (including each proposed extension or reinstatement of an existing collection of information) and to allow 60 days for public comment on the proposed action. Intere | I21: https://www.federalregister.gov/documents/2024/02/07/2024-02444/agency-information-collection-activities-proposed-collection-comment-request | J21: Y | K21: SKIP | L21: PRA paperwork notice
A22: 2024-02445 | B22: Notice | C22: 45329 | E22: 0 | G22: Agency Information Collection Activities: Submission for OMB Review; Comment Request | H22: The Centers for Medicare & Medicaid Services (CMS) is announcing an opportunity for the public to comment on CMS' intention to collect information from the public. Under the Paperwork Reduction Act of 1995 (PRA), federal agencies are required to publish notice in the Federal Register concerning each proposed collection of information, including each proposed extension or reinstatement of an existing collection of information, and to allow a second opportunity for public comment on the notice. In | I22: https://www.federalregister.gov/documents/2024/02/07/2024-02445/agency-information-collection-activities-submission-for-omb-review-comment-request | J22: Y
A23: 2024-07105 | B23: Rule | C23: 45405 | D23: 45446 | E23: 1 | F23: part d(1594); d-snp(1275); ma organization(1179); c-snp(230); part c(202); medicare advantage(128); special needs plan(76); dual eligible(62); medigap(10); medicare supplement(2) | G23: Medicare Program; Changes to the Medicare Advantage and the Medicare Prescription Drug Benefit Program for Contract Year 2024-Remaining Provisions and Contract Year 2025 Policy and Technical Changes to the Medicare Advantage Program, Medicare Prescription Drug Benefit Program, Medicare Cost Plan Program, and Programs of All-Inclusive Care for the Elderly (PACE) | H23: This final rule will revise the Medicare Advantage (Part C), Medicare Prescription Drug Benefit (Part D), Medicare cost plan, and Programs of All-Inclusive Care for the Elderly (PACE) regulations to implement changes related to Star Ratings, marketing and communications, agent/broker compensation, health equity, dual eligible special needs plans (D-SNPs), utilization management, network adequacy, and other programmatic areas. This final rule also codifies existing sub-regulatory guidance in the | I23: https://www.federalregister.gov/documents/2024/04/23/2024-07105/medicare-program-changes-to-the-medicare-advantage-and-the-medicare-prescription-drug-benefit | J23: Y | K23: HIGH | L23: core MA/Part D policy doc (strong kw=2962)
A24: 2024-02631 | B24: Rule | C24: 45331 | D24: 45331 | E24: 0 | G24: Medicare Program: Hospital Outpatient Prospective Payment and Ambulatory Surgical Center Payment Systems; Quality Reporting Programs; Payment for Intensive Outpatient Services in Hospital Outpatient Departments, Community Mental Health Centers, Rural Health Clinics, Federally Qualified Health Centers, and Opioid Treatment Programs; Hospital Price Transparency; Changes to Community Mental Health Centers Conditions of Participation, Changes to the Inpatient Prospective Payment System Medicare Code Editor; Rural Emergency Hospital Conditions of Participation Technical Correction; Correction | H24: This document corrects technical and typographical errors in the final rule with comment period that appeared in the Federal Register on November 22, 2023, titled "Medicare Program: Hospital Outpatient Prospective Payment and Ambulatory Surgical Center Payment Systems; Quality Reporting Programs; Payment for Intensive Outpatient Services in Hospital Outpatient Departments, Community Mental Health Centers, Rural Health Clinics, Federally Qualified Health Centers, and Opioid Treatment Programs; Ho | I24: https://www.federalregister.gov/documents/2024/02/09/2024-02631/medicare-program-hospital-outpatient-prospective-payment-and-ambulatory-surgical-center-payment | J24: Y
A25: 2024-02662 | B25: Notice | C25: 45331 | E25: 0 | G25: Agency Information Collection Activities: Proposed Collection; Comment Request | H25: The Centers for Medicare & Medicaid Services (CMS) is announcing an opportunity for the public to comment on CMS' intention to collect information from the public. Under the Paperwork Reduction Act of 1995 (PRA), Federal agencies are required to publish notice in the Federal Register concerning each proposed collection of information (including each proposed extension or reinstatement of an existing collection of information) and to allow 60 days for public comment on the proposed action. Intere | I25: https://www.federalregister.gov/documents/2024/02/09/2024-02662/agency-information-collection-activities-proposed-collection-comment-request | J25: Y
A26: 2024-02705 | B26: Rule | C26: 45334 | D26: 45334 | E26: 1 | F26: medicare advantage(2) | G26: Medicare and Medicaid Programs; CY 2024 Payment Policies Under the Physician Fee Schedule and Other Changes to Part B Payment and Coverage Policies; Medicare Shared Savings Program Requirements; Medicare Advantage; Medicare and Medicaid Provider and Supplier Enrollment Policies; and Basic Health Program; Corrections | H26: This document corrects technical and typographical errors in the final rule that appeared in the November 16, 2023 issue of the Federal Register, entitled "Medicare and Medicaid Programs; CY 2024 Payment Policies Under the Physician Fee Schedule and Other Changes to Part B Payment and Coverage Policies; Medicare Shared Savings Program Requirements; Medicare Advantage; Medicare and Medicaid Provider and Supplier Enrollment Policies; and Basic Health Program" (referred to hereafter as the "CY 2024 | I26: https://www.federalregister.gov/documents/2024/02/12/2024-02705/medicare-and-medicaid-programs-cy-2024-payment-policies-under-the-physician-fee-schedule-and-other | J26: Y | K26: SKIP | L26: provider payment rule (MA mentions incidental)
A27: 2024-02137 | B27: Proposed Rule | C27: 45337 | E27: 0 | G27: Medicare Program; Strengthening Oversight of Accrediting Organizations (AOs) and Preventing AO Conflict of Interest, and Related Provisions | H27: This proposed rule would set forth a number of provisions to strengthen the oversight of accrediting organizations (AOs) by addressing conflicts of interest, establishing consistent standards, processes and definitions, and updating the validation and performance standards systems. Additionally, this proposed rule would revise the psychiatric hospital survey process, add a limitation on terminated deemed providers and suppliers when reentering the program, and provides technical corrections for | I27: https://www.federalregister.gov/documents/2024/02/15/2024-02137/medicare-program-strengthening-oversight-of-accrediting-organizations-aos-and-preventing-ao-conflict | J27: Y
A28: 2024-03294 | B28: Notice | C28: 45338 | E28: 0 | G28: Agency Information Collection Activities: Proposed Collection; Comment Request | H28: The Centers for Medicare & Medicaid Services (CMS) is announcing an opportunity for the public to comment on CMS' intention to collect information from the public. Under the Paperwork Reduction Act of 1995 (PRA), Federal agencies are required to publish notice in the Federal Register concerning each proposed collection of information (including each proposed extension or reinstatement of an existing collection of information) and to allow 60 days for public comment on the proposed action. Intere | I28: https://www.federalregister.gov/documents/2024/02/16/2024-03294/agency-information-collection-activities-proposed-collection-comment-request | J28: Y
A29: 2024-03344 | B29: Notice | C29: 45342 | E29: 1 | F29: medicare advantage(3); part c(3) | G29: Agency Information Collection Activities: Submission for OMB Review; Comment Request | H29: The Centers for Medicare & Medicaid Services (CMS) is announcing an opportunity for the public to comment on CMS' intention to collect information from the public. Under the Paperwork Reduction Act of 1995 (PRA), Federal agencies are required to publish notice in the Federal Register concerning each proposed collection of information, including each proposed extension or reinstatement of an existing collection of information, and to allow a second opportunity for public comment on the notice. In | I29: https://www.federalregister.gov/documents/2024/02/20/2024-03344/agency-information-collection-activities-submission-for-omb-review-comment-request | J29: Y | K29: SKIP | L29: PRA paperwork notice
A30: 2024-03348 | B30: Notice | C30: 45342 | E30: 0 | G30: Agency Information Collection Activities: Proposed Collection; Comment Request | H30: The Centers for Medicare & Medicaid Services (CMS) is announcing an opportunity for the public to comment on CMS' intention to collect information from the public. Under the Paperwork Reduction Act of 1995 (PRA), Federal agencies are required to publish notice in the Federal Register concerning each proposed collection of information (including each proposed extension or reinstatement of an existing collection of information) and to allow 60 days for public comment on the proposed action. Intere | I30: https://www.federalregister.gov/documents/2024/02/20/2024-03348/agency-information-collection-activities-proposed-collection-comment-request | J30: Y
